Workbook
Name BYT: 'vstupní data'!$B$4
Name BYT: 'vstupní data'!$B$4
Name BYTOVE_DOMY: 'Bytové domy'!$A$1
Name DŮM: 'vstupní data'!$B$3
Name DŮM: 'vstupní data'!$B$3
Name dum_adresa: 'vstupní data'!$D$3
Name EVIDENCE: Evidence!$A$1
Name EXPORT_PRO_SEND_MAIL: 'export send mail'!$A$1
Name FAKTURY_ZA_SLUZBY: 'faktury za služby'!$A$1
Name NAKLADY_BYTOVY_DUM_ZA_ROK: 'Rozpočet domu'!$A$1
Name NAKLADY_BYTOVY_DUM_ZA_ROK: 'Náklady na dům'!$A$1
Name POCET_OSOB: 'Počet osob'!$A$1
Name PREDPISI_PO_MESICI: 'Předpis po mesici'!$B$1
Name PREPLATKY_NEDOPLATKY: 'Přeplatky nedoplatky'!$A$1
Name PRIJEM_SVJ_BEZ_VYDAJU: 'prijem SVJ bez vydaju'!$A$1
Name PRIJEM_SVJ_VCETNE_VYDAJU: 'prijem SVJ'!$A$1
Name Print_Area_Ucto: 'Vyúčtování byt - 1.část'!$A$1:$L$63
Name Print_Area_Ucto: 'Zálohy byt - měsíčně'!$A$1:$Q$35
Name TEPLO: Teplo!$A$1
Name UHRADY: uhrady!$A$1
Name VB_Jednotka_Osvětlení: 'Vyúčtování byt - 1.část'!$C$10
Name VB_Jednotka_Osvětlení: 'Zálohy byt - měsíčně'!$C$10
Name VB_PDF_name: 'Vyúčtování byt - 1.část'!$P$38
Name VB_preplatky_celkem: 'Vyúčtování byt - 1.část'!$K$34
Name VB_preplatky_celkem: 'Zálohy byt - měsíčně'!$P$33
Name VD_celková_plocha_jednotky: 'vstupní data'!$B$25
Name VD_celková_plocha_jednotky: 'vstupní data'!$B$25
Name VD_Cena_BVak: 'vstupní data'!$B$13
Name VD_Cena_BVak: 'vstupní data'!$B$13
Name VD_číslo_účtu_SVJ: 'vstupní data'!$B$22
Name VD_číslo_účtu_SVJ: 'vstupní data'!$B$22
Name VD_externí_výpočet_nákladů_tepla: 'vstupní data'!$B$29
Name VD_externí_výpočet_nákladů_tepla: 'vstupní data'!$B$29
Name vd_faktury_za_sluzby: 'faktury za služby'!$1:$9
Name VD_jméno: 'vstupní data'!$B$5
Name VD_jméno: 'vstupní data'!$B$5
Name VD_odečet_SV_vody_za_daný_rok: 'vstupní data'!$B$23
Name VD_odečet_SV_vody_za_daný_rok: 'vstupní data'!$B$23
Name VD_odečet_TUV_za_daný_rok: 'vstupní data'!$B$24
Name VD_odečet_TUV_za_daný_rok: 'vstupní data'!$B$24
Name VD_Počet_jednotek: 'vstupní data'!$B$17
Name VD_Počet_jednotek: 'vstupní data'!$B$17
Name VD_Počet_komínů: 'vstupní data'!$B$20
Name VD_počet_měsíců_úžívání: 'vstupní data'!$B$15
Name VD_počet_měsíců_úžívání: 'vstupní data'!$B$15
Name VD_Počet_osob: 'vstupní data'!$B$21
Name VD_přeplatek_aktuální_rok: 'vstupní data'!$B$11
Name VD_přeplatek_z_minula: 'vstupní data'!$B$10
Name VD_reklamace_do: 'vstupní data'!$B$14
Name VD_spoluvlastnictví_podíl: 'vstupní data'!$B$27
Name VD_účet_vlastníka: 'vstupní data'!$B$7
Name VD_účet_vlastníka: 'vstupní data'!$B$7
Name VD_účetní_období: 'vstupní data'!$B$8
Name VD_Užitná_plocha_domu_celkem: 'vstupní data'!$B$18
Name VD_Užitná_plocha_domu_započitatelná: 'vstupní data'!$B$19
Name VD_VS: 'vstupní data'!$B$6
Name VD_VS: 'vstupní data'!$B$6
Name VD_vyplaceno_do: 'vstupní data'!$B$16
Name VD_výpočet_vlastnického_podílu: 'vstupní data'!$B$28
Name VD_výpočet_vlastnického_podílu: 'vstupní data'!$B$28

Sheet Zborovská 2 - s vodoměry
A1: =#REF! -> #REF!
A3: =#REF! -> #REF!
A4: =#REF! -> #REF! | C4: =#REF! -> #REF! | F4: =#REF! -> #REF! | H4: =#REF! -> #REF! | J4: =#REF! -> #REF! | K4: =#REF! -> #REF!
A5: =#REF! -> #REF! | C5: =#REF! -> #REF! | F5: =#REF! -> #REF! | H5: =#REF! -> #REF! | J5: =#REF! -> #REF! | K5: =#REF! -> #REF!
A7: =#REF! -> #REF!
E9: =#REF! -> #REF! | H9: =#REF! -> #REF!
A10: =#REF! -> #REF! | C10: =#REF! -> #REF! | D10: =#REF! -> #REF! | E10: =#REF! -> #REF! | F10: =#REF! -> #REF! | G10: =#REF! -> #REF! | H10: =#REF! -> #REF! | I10: =#REF! -> #REF! | J10: =#REF! -> #REF! | K10: =#REF! -> #REF!
A11: =#REF! -> #REF! | C11: =#REF! -> #REF! | D11: =#REF! -> #REF! | E11: =#REF! -> #REF! | F11: =#REF! -> #REF! | G11: =ROUND(E11/F11,2) -> #REF! | H11: =#REF! -> #REF! | I11: =#REF! -> #REF! | J11: =#REF! -> #REF! | K11: =J11-I11 -> #REF!
A12: =#REF! -> #REF! | C12: =#REF! -> #REF! | D12: =#REF! -> #REF! | E12: =#REF! -> #REF! | F12: =#REF! -> #REF! | G12: =ROUND(E12/F12,2) -> #REF! | H12: =#REF! -> #REF! | I12: =#REF! -> #REF! | J12: =#REF! -> #REF! | K12: =J12-I12 -> #REF!
A13: =#REF! -> #REF! | C13: =#REF! -> #REF! | D13: =#REF! -> #REF! | E13: =#REF! -> #REF! | F13: =#REF! -> #REF! | G13: =ROUND(E13/F13,2) -> #REF! | H13: =#REF! -> #REF! | I13: =#REF! -> #REF! | J13: =#REF! -> #REF! | K13: =J13-I13 -> #REF!
A14: =#REF! -> #REF! | C14: =#REF! -> #REF! | D14: =#REF! -> #REF! | E14: =#REF! -> #REF! | F14: ='Počet osob'!P104 -> 307 | G14: =ROUND(E14/F14,2) -> #REF! | H14: =LOOKUP('vstupní data'!B4,'Počet osob'!A:A,'Počet osob'!P:P) -> 0 | I14: =H14*G14 -> #REF! | J14: =#REF! -> #REF! | K14: =J14-I14 -> #REF!
A15: =#REF! -> #REF! | C15: =#REF! -> #REF! | D15: =#REF! -> #REF! | E15: =#REF! -> #REF! | F15: =#REF! -> #REF! | G15: =#REF! -> #REF! | H15: =#REF! -> #REF! | I15: =#REF! -> #REF! | J15: =#REF! -> #REF! | K15: =#REF! -> #REF!
A16: =#REF! -> #REF! | C16: =#REF! -> #REF! | D16: =#REF! -> #REF! | E16: =#REF! -> #REF! | F16: =#REF! -> #REF! | G16: =#REF! -> #REF! | H16: =#REF! -> #REF! | I16: =#REF! -> #REF! | J16: =#REF! -> #REF! | K16: =#REF! -> #REF!
A17: =#REF! -> #REF! | C17: =#REF! -> #REF! | D17: =#REF! -> #REF! | E17: =#REF! -> #REF! | F17: =#REF! -> #REF! | G17: =#REF! -> #REF! | H17: =#REF! -> #REF! | I17: =#REF! -> #REF! | J17: =#REF! -> #REF! | K17: =#REF! -> #REF!
A18: =#REF! -> #REF! | C18: =#REF! -> #REF! | D18: =#REF! -> #REF! | E18: ='faktury za služby'!J43 -> 13181.67 | F18: =#REF! -> #REF! | G18: =ROUND(E18/F18,2) -> #REF! | H18: =#REF! -> #REF! | I18: =#REF! -> #REF! | J18: =#REF! -> #REF! | K18: =J18-I18 -> #REF!
A19: =#REF! -> #REF! | C19: =#REF! -> #REF! | D19: =#REF! -> #REF! | E19: =#REF! -> #REF! | F19: =#REF! -> #REF! | G19: =#REF! -> #REF! | H19: =#REF! -> #REF! | I19: =#REF! -> #REF! | J19: =#REF! -> #REF! | K19: =#REF! -> #REF!
C20: =#REF! -> #REF! | D20: =#REF! -> #REF! | E20: =#REF! -> #REF! | F20: =#REF! -> #REF! | G20: =#REF! -> #REF! | H20: =#REF! -> #REF! | I20: =#REF! -> #REF!
A21: =#REF! -> #REF! | C21: =#REF! -> #REF! | D21: =#REF! -> #REF! | E21: =#REF! -> #REF! | F21: =#REF! -> #REF! | G21: =ROUND(E21/F21,2) -> #REF! | H21: =#REF! -> #REF! | I21: =#REF! -> #REF! | J21: =#REF! -> #REF! | K21: =J21-I21 -> #REF!
A22: =#REF! -> #REF! | C22: =#REF! -> #REF! | D22: =#REF! -> #REF! | E22: =#REF! -> #REF! | F22: =#REF! -> #REF! | G22: =#REF! -> #REF! | H22: =#REF! -> #REF! | I22: =#REF! -> #REF! | J22: =#REF! -> #REF! | K22: =#REF! -> #REF!
A23: =#REF! -> #REF! | E23: =SUM(E11:E21) -> #REF! | G23: =#REF! -> #REF! | I23: =SUM(I11:I21) -> #REF! | J23: =SUM(J11:J21) -> #REF! | K23: =SUM(K11:K21) -> #REF!
G24: =#REF! -> #REF! | K24: =#REF! -> #REF!
G25: =#REF! -> #REF! | K25: =K24+K23 -> #REF!
E26: =#REF! -> #REF!
A28: =#REF! -> #REF!
A29: =#REF! -> #REF! | B29: =#REF! -> #REF! | C29: =#REF! -> #REF! | D29: =#REF! -> #REF! | E29: =#REF! -> #REF! | F29: =#REF! -> #REF! | G29: =#REF! -> #REF! | H29: =#REF! -> #REF! | ... L29: =#REF! -> #REF!
A30: =#REF! -> #REF! | B30: =#REF! -> #REF! | C30: =#REF! -> #REF! | D30: =#REF! -> #REF! | E30: =#REF! -> #REF! | F30: =#REF! -> #REF! | G30: =#REF! -> #REF! | H30: =#REF! -> #REF! | ... L30: =#REF! -> #REF!
A31: =#REF! -> #REF!
A32: =#REF! -> #REF! | B32: =#REF! -> #REF! | C32: =#REF! -> #REF! | D32: =#REF! -> #REF! | E32: =#REF! -> #REF! | F32: =#REF! -> #REF! | G32: =#REF! -> #REF! | H32: =#REF! -> #REF! | ... L32: =#REF! -> #REF!
A33: =#REF! -> #REF! | B33: =#REF! -> #REF! | C33: =#REF! -> #REF! | D33: =#REF! -> #REF! | E33: =#REF! -> #REF! | F33: =#REF! -> #REF! | G33: =#REF! -> #REF! | H33: =#REF! -> #REF! | ... L33: =#REF! -> #REF!
A34: =#REF! -> #REF! | C34: =#REF! -> #REF!
A36: =#REF! -> #REF!
A37: =#REF! -> #REF! | C37: =#REF! -> #REF! | E37: =#REF! -> #REF! | G37: =#REF! -> #REF! | I37: =#REF! -> #REF! | K37: =#REF! -> #REF!
A38: =#REF! -> #REF! | C38: =#REF! -> #REF! | E38: =#REF! -> #REF! | G38: =#REF! -> #REF! | I38: =#REF! -> #REF! | K38: =#REF! -> #REF!
A39: =#REF! -> #REF! | C39: =#REF! -> #REF! | E39: =#REF! -> #REF! | G39: =#REF! -> #REF! | I39: =#REF! -> #REF! | K39: =#REF! -> #REF!
A41: =#REF! -> #REF!
A42: =#REF! -> #REF!
A43: =#REF! -> #REF!
A44: =#REF! -> #REF!

Sheet Zborovská 2 - bez vodoměrů
A1: =#REF! -> #REF!
A3: =#REF! -> #REF!
A4: =#REF! -> #REF! | C4: =#REF! -> #REF! | F4: =#REF! -> #REF! | H4: =#REF! -> #REF! | J4: =#REF! -> #REF! | K4: =#REF! -> #REF!
A5: =#REF! -> #REF! | C5: =#REF! -> #REF! | F5: =#REF! -> #REF! | H5: =#REF! -> #REF! | J5: =#REF! -> #REF! | K5: =#REF! -> #REF!
A7: =#REF! -> #REF!
E9: =#REF! -> #REF! | H9: =#REF! -> #REF!
A10: =#REF! -> #REF! | C10: =#REF! -> #REF! | D10: =#REF! -> #REF! | E10: =#REF! -> #REF! | F10: =#REF! -> #REF! | G10: =#REF! -> #REF! | H10: =#REF! -> #REF! | I10: =#REF! -> #REF! | J10: =#REF! -> #REF! | K10: =#REF! -> #REF!
A11: =#REF! -> #REF! | C11: =#REF! -> #REF! | D11: =#REF! -> #REF! | E11: =#REF! -> #REF! | F11: =#REF! -> #REF! | G11: =ROUND(E11/F11,2) -> #REF! | H11: =#REF! -> #REF! | I11: =G11*H11 -> #REF! | J11: =#REF! -> #REF! | K11: =#REF! -> #REF!
A12: =#REF! -> #REF! | C12: =#REF! -> #REF! | D12: =#REF! -> #REF! | E12: =#REF! -> #REF! | F12: =#REF! -> #REF! | G12: =ROUND(E12/F12,2) -> #REF! | H12: =#REF! -> #REF! | I12: =G12*H12 -> #REF! | J12: =#REF! -> #REF! | K12: =#REF! -> #REF!
A13: =#REF! -> #REF! | C13: =#REF! -> #REF! | D13: =#REF! -> #REF! | E13: =#REF! -> #REF! | F13: =#REF! -> #REF! | G13: =ROUND(E13/F13,2) -> #REF! | H13: =#REF! -> #REF! | I13: =G13*H13 -> #REF! | J13: =#REF! -> #REF! | K13: =#REF! -> #REF!
A14: =#REF! -> #REF! | C14: =#REF! -> #REF! | D14: =#REF! -> #REF! | E14: =#REF! -> #REF! | F14: ='Počet osob'!P104 -> 307 | G14: =ROUND(E14/F14,2) -> #REF! | H14: =LOOKUP('vstupní data'!B4,'Počet osob'!A:A,'Počet osob'!P:P) -> 0 | I14: =G14*H14 -> #REF! | J14: =#REF! -> #REF! | K14: =J14-I14 -> #REF!
A15: =#REF! -> #REF! | C15: =#REF! -> #REF! | D15: =#REF! -> #REF! | E15: =#REF! -> #REF! | F15: =#REF! -> #REF! | G15: =#REF! -> #REF! | H15: =#REF! -> #REF! | I15: =#REF! -> #REF! | J15: =#REF! -> #REF! | K15: =#REF! -> #REF!
A16: =#REF! -> #REF! | C16: =#REF! -> #REF! | D16: =#REF! -> #REF! | E16: =#REF! -> #REF! | F16: =#REF! -> #REF! | G16: =#REF! -> #REF! | H16: =#REF! -> #REF! | I16: =#REF! -> #REF! | J16: =#REF! -> #REF! | K16: =#REF! -> #REF!
A17: =#REF! -> #REF! | C17: =#REF! -> #REF! | D17: =#REF! -> #REF! | E17: =#REF! -> #REF! | F17: =#REF! -> #REF! | G17: =#REF! -> #REF! | H17: =#REF! -> #REF! | I17: =#REF! -> #REF! | J17: =#REF! -> #REF! | K17: =#REF! -> #REF!
A18: =#REF! -> #REF! | C18: =#REF! -> #REF! | D18: =#REF! -> #REF! | E18: ='faktury za služby'!J42 -> 75347.33 | F18: ='Počet osob'!Q104 -> 439 | G18: =ROUND(E18/F18,2) -> 171.63 | H18: =#REF! -> #REF! | I18: =G18*H18 -> #REF! | J18: =#REF! -> #REF! | K18: =#REF! -> #REF!
A19: =#REF! -> #REF! | C19: =#REF! -> #REF! | D19: =#REF! -> #REF! | E19: =#REF! -> #REF! | F19: =#REF! -> #REF! | G19: =#REF! -> #REF! | H19: =#REF! -> #REF! | I19: =#REF! -> #REF! | J19: =#REF! -> #REF! | K19: =#REF! -> #REF!
C20: =#REF! -> #REF! | D20: =#REF! -> #REF! | E20: =#REF! -> #REF! | F20: =#REF! -> #REF! | G20: =#REF! -> #REF! | H20: =#REF! -> #REF! | I20: =#REF! -> #REF!
A21: =#REF! -> #REF! | C21: =#REF! -> #REF! | D21: =#REF! -> #REF! | E21: =#REF! -> #REF! | F21: =#REF! -> #REF! | G21: =ROUND(E21/F21,2) -> #REF! | H21: =#REF! -> #REF! | I21: =G21*H21 -> #REF! | J21: =#REF! -> #REF! | K21: =#REF! -> #REF!
A22: =#REF! -> #REF! | C22: =#REF! -> #REF! | D22: =#REF! -> #REF! | E22: =#REF! -> #REF! | F22: =#REF! -> #REF! | G22: =#REF! -> #REF! | H22: =#REF! -> #REF! | I22: =#REF! -> #REF! | J22: =#REF! -> #REF! | K22: =#REF! -> #REF!
A23: =#REF! -> #REF! | E23: =SUM(E11:E21) -> #REF! | G23: =#REF! -> #REF! | I23: =SUM(I11:I21) -> #REF! | J23: =SUM(J11:J21) -> #REF! | K23: =SUM(K11:K21) -> #REF!
G24: =#REF! -> #REF! | K24: =#REF! -> #REF!
G25: =#REF! -> #REF! | K25: =K23+K24 -> #REF!
E26: =#REF! -> #REF!
A28: =#REF! -> #REF!
A29: =#REF! -> #REF! | B29: =#REF! -> #REF! | C29: =#REF! -> #REF! | D29: =#REF! -> #REF! | E29: =#REF! -> #REF! | F29: =#REF! -> #REF! | G29: =#REF! -> #REF! | H29: =#REF! -> #REF! | ... L29: =#REF! -> #REF!
A30: =#REF! -> #REF! | B30: =#REF! -> #REF! | C30: =#REF! -> #REF! | D30: =#REF! -> #REF! | E30: =#REF! -> #REF! | F30: =#REF! -> #REF! | G30: =#REF! -> #REF! | H30: =#REF! -> #REF! | ... L30: =#REF! -> #REF!
A31: =#REF! -> #REF!
A32: =#REF! -> #REF! | B32: =#REF! -> #REF! | C32: =#REF! -> #REF! | D32: =#REF! -> #REF! | E32: =#REF! -> #REF! | F32: =#REF! -> #REF! | G32: =#REF! -> #REF! | H32: =#REF! -> #REF! | ... L32: =#REF! -> #REF!
A33: =#REF! -> #REF! | B33: =#REF! -> #REF! | C33: =#REF! -> #REF! | D33: =#REF! -> #REF! | E33: =#REF! -> #REF! | F33: =#REF! -> #REF! | G33: =#REF! -> #REF! | H33: =#REF! -> #REF! | ... L33: =#REF! -> #REF!
A34: =#REF! -> #REF! | C34: =#REF! -> #REF!
A36: =#REF! -> #REF!
A37: =#REF! -> #REF! | C37: =#REF! -> #REF! | E37: =#REF! -> #REF! | G37: =#REF! -> #REF! | I37: =#REF! -> #REF! | K37: =#REF! -> #REF!
A38: =#REF! -> #REF! | C38: =#REF! -> #REF! | E38: =#REF! -> #REF! | G38: =#REF! -> #REF! | I38: =#REF! -> #REF! | K38: =#REF! -> #REF!
A39: =#REF! -> #REF! | C39: =#REF! -> #REF! | E39: =#REF! -> #REF! | G39: =#REF! -> #REF! | I39: =#REF! -> #REF! | K39: =#REF! -> #REF!
A41: =#REF! -> #REF!
A42: =#REF! -> #REF!
A43: =#REF! -> #REF!
A44: =#REF! -> #REF!

Sheet export send mail
B1: Email | C1: Celé jméno | D1: Stav | E1: Mobil | F1: Jméno | G1: Příjmení | H1: ID | I1: Adresa | J1: Bytový dům | K1: Jednotka číslo | L1: Soubor na poslání | M1: Datum narození | N1: Oslovení | O1: Příloha 2 | Q1: SEZNAM
B2: =Evidence!D2 -> martin.k_2003@volny.cz | C2: =Evidence!B2 -> Martin Klíma | E2: =Evidence!E2 -> 607252477 | I2: =Evidence!C2 -> Zborovská 939/2, 616 00 Brno | J2: =dum_adresa -> Zborovská 939/2, Žabovřesky, 616 00 Brno | K2: =Evidence!A2 -> Byt č. 939/01 | L2: =("C:\sprava\"&SUBSTITUTE(K2,"/","")&".pdf") -> C:\sprava\Byt č. 93901.pdf | N2: Vážený pane Klímo,
B3: =Evidence!D3 -> volodymyr_polovko@mail.ru | C3: =Evidence!B3 -> Volodymyr Polovko | E3: =Evidence!E3 -> 776425566 | I3: =Evidence!C3 -> Zborovská 939/2, 61600 Brno | J3: =dum_adresa -> Zborovská 939/2, Žabovřesky, 616 00 Brno | K3: =Evidence!A3 -> Byt č. 939/02 | L3: =("C:\sprava\"&SUBSTITUTE(K3,"/","")&".pdf") -> C:\sprava\Byt č. 93902.pdf | N3: Vážený pane Polovko,
B4: =Evidence!D4 -> VeronikaTeplikova@seznam.cz | C4: =Evidence!B4 -> Veronika Teplíková | E4: =Evidence!E4 -> 728608587 | I4: =Evidence!C4 -> Těšice 600, 696 19 Mikulčice | J4: =dum_adresa -> Zborovská 939/2, Žabovřesky, 616 00 Brno | K4: =Evidence!A4 -> Byt č. 939/03 | L4: =("C:\sprava\"&SUBSTITUTE(K4,"/","")&".pdf") -> C:\sprava\Byt č. 93903.pdf | N4: Vážená paní Teplíková,
B5: =Evidence!D5 -> kotek.vladimir@gmail.com | C5: =Evidence!B5 -> D.A.B. Property s.r.o. | E5: =Evidence!E5 -> 603 792 968 | I5: =Evidence!C5 -> Pastviny 645/3, 624 00 Brno | J5: =dum_adresa -> Zborovská 939/2, Žabovřesky, 616 00 Brno | K5: =Evidence!A5 -> Byt č. 939/04 | L5: =("C:\sprava\"&SUBSTITUTE(K5,"/","")&".pdf") -> C:\sprava\Byt č. 93904.pdf | N5: Vážený pane inženýre,
B6: =Evidence!D6 -> jana.van@post.cz | C6: =Evidence!B6 -> Jana Vaňková | E6: =Evidence!E6 -> 774229922 | I6: =Evidence!C6 -> č. p. 276, 66404 Hostěnice | J6: =dum_adresa -> Zborovská 939/2, Žabovřesky, 616 00 Brno | K6: =Evidence!A6 -> Byt č. 939/05 | L6: =("C:\sprava\"&SUBSTITUTE(K6,"/","")&".pdf") -> C:\sprava\Byt č. 93905.pdf | N6: Vážená paní Vaňková,
B7: =Evidence!D7 -> milan.kost@email.cz | C7: =Evidence!B7 -> Ing. Milan Kosť | E7: =Evidence!E7 -> 777338203 | I7: =Evidence!C7 -> 42, 570 01 Poříčí u Litomyšle | J7: =dum_adresa -> Zborovská 939/2, Žabovřesky, 616 00 Brno | K7: =Evidence!A7 -> Byt č. 939/06 | L7: =("C:\sprava\"&SUBSTITUTE(K7,"/","")&".pdf") -> C:\sprava\Byt č. 93906.pdf | N7: Vážený pane inženýre,
B8: =Evidence!D8 -> ernest.biros@fnusa.cz | C8: =Evidence!B8 -> MUDr. Ernest Biroš | E8: =Evidence!E8 -> 776 235 263 | I8: =Evidence!C8 -> Újezdy 590/11,614 00 Brno | J8: =dum_adresa -> Zborovská 939/2, Žabovřesky, 616 00 Brno | K8: =Evidence!A8 -> Byt č. 939/07 | L8: =("C:\sprava\"&SUBSTITUTE(K8,"/","")&".pdf") -> C:\sprava\Byt č. 93907.pdf | N8: Vážený pane doktore,
B9: =Evidence!D9 -> vorba@volny.cz | C9: =Evidence!B9 -> Ing. Miloš Vorba | E9: =Evidence!E9 -> 608632338 | I9: =Evidence!C9 -> Zborovská 939/2, 616 00 Brno-Žabovřesky | J9: =dum_adresa -> Zborovská 939/2, Žabovřesky, 616 00 Brno | K9: =Evidence!A9 -> Byt č. 939/08 | L9: =("C:\sprava\"&SUBSTITUTE(K9,"/","")&".pdf") -> C:\sprava\Byt č. 93908.pdf | N9: Vážený pane inženýre,
B10: =Evidence!D10 -> milan.kost@email.cz | C10: =Evidence!B10 -> Ing. Milan Kosť | E10: =Evidence!E10 -> 777338203 | I10: =Evidence!C10 -> 42, 570 01 Poříčí u Litomyšle | J10: =dum_adresa -> Zborovská 939/2, Žabovřesky, 616 00 Brno | K10: =Evidence!A10 -> Byt č. 939/09 | L10: =("C:\sprava\"&SUBSTITUTE(K10,"/","")&".pdf") -> C:\sprava\Byt č. 93909.pdf | N10: Vážený pane inženýre,
B11: =Evidence!D11 -> jojkos@gmail.com | C11: =Evidence!B11 -> Jonáš Holcner | E11: =Evidence!E11 -> 721334220 | I11: =Evidence!C11 -> Dobrovského 1872/88, 612 00 Brno | J11: =dum_adresa -> Zborovská 939/2, Žabovřesky, 616 00 Brno | K11: =Evidence!A11 -> Byt č. 939/10 | L11: =("C:\sprava\"&SUBSTITUTE(K11,"/","")&".pdf") -> C:\sprava\Byt č. 93910.pdf | N11: Vážený pane Holcnere,
B12: =Evidence!D12 -> jbrandtner@me.com | C12: =Evidence!B12 -> Jiří Brandtner | E12: =Evidence!E12 -> 724672451 | I12: =Evidence!C12 -> Nad kašnou 1157/21, 635 00 Brno-Bystrc | J12: =dum_adresa -> Zborovská 939/2, Žabovřesky, 616 00 Brno | K12: =Evidence!A12 -> Byt č. 939/11 | L12: =("C:\sprava\"&SUBSTITUTE(K12,"/","")&".pdf") -> C:\sprava\Byt č. 93911.pdf | N12: Vážený pane Brandtnere,
B13: =Evidence!D13 -> pkucernakova@seznam.cz | C13: =Evidence!B13 -> Patricie Kučerňáková | E13: =Evidence!E13 -> 773963451 | I13: =Evidence!C13 -> Hlavní 6, 667 01 Vojkovice | J13: =dum_adresa -> Zborovská 939/2, Žabovřesky, 616 00 Brno | K13: =Evidence!A13 -> Byt č. 939/12 | L13: =("C:\sprava\"&SUBSTITUTE(K13,"/","")&".pdf") -> C:\sprava\Byt č. 93912.pdf | N13: Vážená paní Kučerňáková,
... B59: =Evidence!D59 -> 0 | C59: =Evidence!B59 -> 0 | E59: =Evidence!E59 -> 0 | I59: =Evidence!C59 -> 0 | J59: =dum_adresa -> Zborovská 939/2, Žabovřesky, 616 00 Brno | K59: =Evidence!A59 -> 0 | L59: =("C:\sprava\"&SUBSTITUTE(K59,"/","")&".pdf") -> C:\sprava\0.pdf | N59: Vážený pane inženýre,
B60: =Evidence!D60 -> 0 | C60: =Evidence!B60 -> 0 | E60: =Evidence!E60 -> 0 | I60: =Evidence!C60 -> 0 | J60: =dum_adresa -> Zborovská 939/2, Žabovřesky, 616 00 Brno | K60: =Evidence!A60 -> 0 | L60: =("C:\sprava\"&SUBSTITUTE(K60,"/","")&".pdf") -> C:\sprava\0.pdf
B61: =Evidence!D61 -> 0 | C61: =Evidence!B61 -> 0 | E61: =Evidence!E61 -> 0 | I61: =Evidence!C61 -> 0 | J61: =dum_adresa -> Zborovská 939/2, Žabovřesky, 616 00 Brno | K61: =Evidence!A61 -> 0 | L61: =("C:\sprava\"&SUBSTITUTE(K61,"/","")&".pdf") -> C:\sprava\0.pdf
B62: =Evidence!D62 -> 0 | C62: =Evidence!B62 -> 0 | E62: =Evidence!E62 -> 0 | I62: =Evidence!C62 -> 0 | J62: =dum_adresa -> Zborovská 939/2, Žabovřesky, 616 00 Brno | K62: =Evidence!A62 -> 0 | L62: =("C:\sprava\"&SUBSTITUTE(K62,"/","")&".pdf") -> C:\sprava\0.pdf
B63: =Evidence!D63 -> 0 | C63: =Evidence!B63 -> 0 | E63: =Evidence!E63 -> 0 | I63: =Evidence!C63 -> 0 | J63: =dum_adresa -> Zborovská 939/2, Žabovřesky, 616 00 Brno | K63: =Evidence!A63 -> 0 | L63: =("C:\sprava\"&SUBSTITUTE(K63,"/","")&".pdf") -> C:\sprava\0.pdf
B64: =Evidence!D64 -> 0 | C64: =Evidence!B64 -> 0 | E64: =Evidence!E64 -> 0 | I64: =Evidence!C64 -> 0 | J64: =dum_adresa -> Zborovská 939/2, Žabovřesky, 616 00 Brno | K64: =Evidence!A64 -> 0 | L64: =("C:\sprava\"&SUBSTITUTE(K64,"/","")&".pdf") -> C:\sprava\0.pdf
B65: =Evidence!D65 -> 0 | C65: =Evidence!B65 -> 0 | E65: =Evidence!E65 -> 0 | I65: =Evidence!C65 -> 0 | J65: =dum_adresa -> Zborovská 939/2, Žabovřesky, 616 00 Brno | K65: =Evidence!A65 -> 0 | L65: =("C:\sprava\"&SUBSTITUTE(K65,"/","")&".pdf") -> C:\sprava\0.pdf
B66: =Evidence!D66 -> 0 | C66: =Evidence!B66 -> 0 | E66: =Evidence!E66 -> 0 | I66: =Evidence!C66 -> 0 | J66: =dum_adresa -> Zborovská 939/2, Žabovřesky, 616 00 Brno | K66: =Evidence!A66 -> 0 | L66: =("C:\sprava\"&SUBSTITUTE(K66,"/","")&".pdf") -> C:\sprava\0.pdf
B67: =Evidence!D67 -> 0 | C67: =Evidence!B67 -> 0 | E67: =Evidence!E67 -> 0 | I67: =Evidence!C67 -> 0 | J67: =dum_adresa -> Zborovská 939/2, Žabovřesky, 616 00 Brno | K67: =Evidence!A67 -> 0 | L67: =("C:\sprava\"&SUBSTITUTE(K67,"/","")&".pdf") -> C:\sprava\0.pdf
B68: =Evidence!D68 -> 0 | C68: =Evidence!B68 -> 0 | E68: =Evidence!E68 -> 0 | I68: =Evidence!C68 -> 0 | J68: =dum_adresa -> Zborovská 939/2, Žabovřesky, 616 00 Brno | K68: =Evidence!A68 -> 0 | L68: =("C:\sprava\"&SUBSTITUTE(K68,"/","")&".pdf") -> C:\sprava\0.pdf
B69: =Evidence!D69 -> 0 | C69: =Evidence!B69 -> 0 | E69: =Evidence!E69 -> 0 | I69: =Evidence!C69 -> 0 | J69: =dum_adresa -> Zborovská 939/2, Žabovřesky, 616 00 Brno | K69: =Evidence!A69 -> 0 | L69: =("C:\sprava\"&SUBSTITUTE(K69,"/","")&".pdf") -> C:\sprava\0.pdf
B70: =Evidence!D70 -> 0 | C70: =Evidence!B70 -> 0 | E70: =Evidence!E70 -> 0 | I70: =Evidence!C70 -> 0 | J70: =dum_adresa -> Zborovská 939/2, Žabovřesky, 616 00 Brno | K70: =Evidence!A70 -> 0 | L70: =("C:\sprava\"&SUBSTITUTE(K70,"/","")&".pdf") -> C:\sprava\0.pdf
B71: =Evidence!D71 -> 0 | C71: =Evidence!B71 -> 0 | E71: =Evidence!E71 -> 0 | I71: =Evidence!C71 -> 0 | J71: =dum_adresa -> Zborovská 939/2, Žabovřesky, 616 00 Brno | K71: =Evidence!A71 -> 0 | L71: =("C:\sprava\"&SUBSTITUTE(K71,"/","")&".pdf") -> C:\sprava\0.pdf
... B232: =Evidence!D232 -> 0 | C232: =Evidence!B232 -> 0 | E232: =Evidence!E232 -> 0 | I232: =Evidence!C232 -> 0 | J232: =dum_adresa -> Zborovská 939/2, Žabovřesky, 616 00 Brno | K232: =Evidence!A232 -> 0 | L232: =("C:\sprava\"&SUBSTITUTE(K232,"/","")&".pdf") -> C:\sprava\0.pdf

Sheet Zálohy byt - měsíčně
A1: AdminReal s.r.o., Veveří 2581/102 , 616 00 Brno, IČO 02827476, Zapsáno KS v Brně, oddíl C, vložka 82606
A2: ='vstupní data'!B5 -> Martin Klíma | S2: MENU
A3: adresa společenství: | C3: =dum_adresa -> Zborovská 939/2, Žabovřesky, 616 00 Brno | F3: bankovní spojení člena: | H3: ='vstupní data'!B7 -> 8308679001/5500 | K3: č. prostoru: | P3: ='vstupní data'!B4 -> Byt č. 939/01
A4: bankovní spojení společenství: | C4: ='vstupní data'!B22 -> 2100704207/2010 | E4: variabilní symbol pro platbu nedoplatku: | H4: ='vstupní data'!B6 -> 1093900019 | K4: zůčtovací období: | P4: =IF('vstupní data'!D15="první část roku",'vstupní data'!E17,'vstupní data'!H17) -> 1.1.2024 - 31.12.2024
O6: POČET OSOB | P6: =IF(P7 > 0, "Navýšení předpisu o částku", "Snížení předpisu o částku") -> Navýšení předpisu o částku | Q6: Navýšení předpis o částku (ručně)
O7: ='vstupní data'!AJ30 -> 4 | P7: =IF(Q7=0, IF(A38>0, -ROUND((A38*0.95)/VD_počet_měsíců_úžívání, 0), -ROUND((A38*1.05)/VD_počet_měsíců_úžívání, 0)), Q7) -> 5 | Q7: 5 | R7: * pokud nula vypočítá si sám pokud se zadá vezme dané číslo
E8: Odběrné místo (dům) | H8: Uživatel
A9: Položka | B9: Sloupec1 | C9: Jednotka | D9: Podíl | E9: Náklad | F9: Jednotek | G9: Kč/jedn | H9: Jednotek2 | I9: Záloha (aktuální) | J9: Náklad za rok | K9: Nový náklad -+% | L9: Přeplatky | nedoplatky | M9: Záloha měsíčně (aktuální) | N9: Záloha měsíčně (nová do OS po navýšení o %) | O9: Záloha měsíčně (dle počtu osob) | P9: Záloha měsíčně (nová do OS po navýšení o částku) | Q9: Navýšení o kolik procent?
A10: =Faktury!A4 -> Elektrická energie (společné prostory) | C10: =Faktury!C4 -> počet osob | D10: =Faktury!D4 -> 100 | E10: =Faktury!E4 -> 8663.77 | F10: =Faktury!F4 -> 439 | G10: =Faktury!G4 -> 19.74 | H10: =Faktury!H4 -> 48 | I10: ='Vyúčtování byt - 1.část'!J10 -> 540 | J10: =Faktury!I4 -> 947.52 | K10: =IF(J10=0,0,J10*(100+Q10)/100) -> 947.52 | L10: ='Vyúčtování byt - 1.část'!K10 -> -407.52 | M10: =ROUND(I10/VD_počet_měsíců_úžívání,2) -> 45 | N10: =IF(C10="počet osob", CEILING(K10/'vstupní data'!$AJ$31/VD_počet_měsíců_úžívání*($O$7*12), 10), ROUNDUP(K10/VD_počet_měsíců_úžívání, -1)) -> 80 | O10: =CEILING(K10/'vstupní data'!$AJ$31/VD_počet_měsíců_úžívání*($O$7*12),10) -> 80 | P10: =ROUND(MAX(0,I10/VD_počet_měsíců_úžívání-IF($P$7>0,L10/VD_počet_měsíců_úžívání*1.05,L10/VD_počet_měsíců_úžívání*0.95)),0) -> 81 | Q10: 0
A11: =Faktury!A5 -> Úklid bytového domu | C11: =Faktury!C5 -> počet osob | D11: =Faktury!D5 -> 100 | E11: =Faktury!E5 -> 25800 | F11: =Faktury!F5 -> 439 | G11: =Faktury!G5 -> 58.77 | H11: =Faktury!H5 -> 48 | I11: ='Vyúčtování byt - 1.část'!J11 -> 3000 | J11: =Faktury!I5 -> 2820.96 | K11: =IF(J11=0,0,J11*(100+Q11)/100) -> 2820.96 | L11: ='Vyúčtování byt - 1.část'!K11 -> 179.04 | M11: =ROUND(I11/VD_počet_měsíců_úžívání,2) -> 250 | N11: =IF(C11="počet osob", CEILING(K11/'vstupní data'!$AJ$31/VD_počet_měsíců_úžívání*($O$7*12), 10), ROUNDUP(K11/VD_počet_měsíců_úžívání, -1)) -> 240 | O11: =CEILING(K11/'vstupní data'!$AJ$31/VD_počet_měsíců_úžívání*($O$7*12),10) -> 240 | P11: =ROUND(MAX(0,I11/VD_počet_měsíců_úžívání-IF($P$7>0,L11/VD_počet_měsíců_úžívání*1.05,L11/VD_počet_měsíců_úžívání*0.95)),0) -> 234 | Q11: 0
A12: =Faktury!A6 -> Komíny | C12: =Faktury!C6 -> komín | D12: =Faktury!D6 -> 100 | E12: =Faktury!E6 -> 7502 | F12: =Faktury!F6 -> 12 | G12: =Faktury!G6 -> 625.17 | H12: =Faktury!H6 -> 1 | I12: ='Vyúčtování byt - 1.část'!J12 -> 540 | J12: =Faktury!I6 -> 625.17 | K12: =IF(J12=0,0,J12*(100+Q12)/100) -> 625.17 | L12: ='Vyúčtování byt - 1.část'!K12 -> -85.17 | M12: =ROUND(I12/VD_počet_měsíců_úžívání,2) -> 45 | N12: =IF(C12="počet osob", CEILING(K12/'vstupní data'!$AJ$31/VD_počet_měsíců_úžívání*($O$7*12), 10), ROUNDUP(K12/VD_počet_měsíců_úžívání, -1)) -> 60 | O12: =CEILING(K12/'vstupní data'!$AJ$31/VD_počet_měsíců_úžívání*($O$7*12),10) -> 60 | P12: =ROUND(MAX(0,I12/VD_počet_měsíců_úžívání-IF($P$7>0,L12/VD_počet_měsíců_úžívání*1.05,L12/VD_počet_měsíců_úžívání*0.95)),0) -> 52 | Q12: 0
A13: =Faktury!A7 -> Pravidelná údržba výtah | C13: =Faktury!C7 -> počet osob | D13: =Faktury!D7 -> 100 | E13: =Faktury!E7 -> 43616.12 | F13: =Faktury!F7 -> 307 | G13: =Faktury!G7 -> 142.07 | H13: =Faktury!H7 -> 0 | I13: ='Vyúčtování byt - 1.část'!J13 -> 0 | J13: =Faktury!I7 -> 0 | K13: =IF(J13=0,0,J13*(100+Q13)/100) -> 0 | L13: ='Vyúčtování byt - 1.část'!K13 -> 0 | M13: =ROUND(I13/VD_počet_měsíců_úžívání,2) -> 0 | N13: =IF(C13="počet osob", CEILING(K13/'vstupní data'!$AJ$31/VD_počet_měsíců_úžívání*($O$7*12), 10), ROUNDUP(K13/VD_počet_měsíců_úžívání, -1)) -> 0 | O13: =CEILING(K13/'vstupní data'!$AJ$31/VD_počet_měsíců_úžívání*($O$7*12),10) -> 0 | P13: =ROUND(MAX(0,I13/VD_počet_měsíců_úžívání-IF($P$7>0,L13/VD_počet_měsíců_úžívání*1.05,L13/VD_počet_měsíců_úžívání*0.95)),0) -> 0 | Q13: 0
A14: =Faktury!A17 -> Fond oprav nebytových prostor | C14: =Faktury!C17 -> 0 | D14: =Faktury!D17 -> 0 | E14: =Faktury!E17 -> 0 | F14: =Faktury!F17 -> 0 | G14: =Faktury!G17 -> 0 | H14: =Faktury!H17 -> 0 | I14: ='Vyúčtování byt - 1.část'!J14 -> 0 | J14: =Faktury!I17 -> 0 | K14: =IF(J14=0,0,J14*(100+Q14)/100) -> 0 | L14: ='Vyúčtování byt - 1.část'!K14 -> 0 | M14: =ROUND(I14/VD_počet_měsíců_úžívání,2) -> 0 | N14: =IF(C14="počet osob", CEILING(K14/'vstupní data'!$AJ$31/VD_počet_měsíců_úžívání*($O$7*12), 10), ROUNDUP(K14/VD_počet_měsíců_úžívání, -1)) -> 0 | O14: =CEILING(K14/'vstupní data'!$AJ$31/VD_počet_měsíců_úžívání*($O$7*12),10) -> 0 | P14: =ROUND(MAX(0,I14/VD_počet_měsíců_úžívání-IF($P$7>0,L14/VD_počet_měsíců_úžívání*1.05,L14/VD_počet_měsíců_úžívání*0.95)),0) -> 0 | Q14: 0
A15: =Faktury!A12 -> Pojištění domu | C15: =Faktury!C12 -> 0 | D15: =Faktury!D12 -> 0 | E15: =Faktury!E12 -> 0 | F15: =Faktury!F12 -> 0 | G15: =Faktury!G12 -> 0 | H15: =Faktury!H12 -> 0 | I15: ='Vyúčtování byt - 1.část'!J15 -> 0 | J15: =Faktury!I12 -> 0 | K15: =IF(J15=0,0,J15*(100+Q15)/100) -> 0 | L15: ='Vyúčtování byt - 1.část'!K15 -> 0 | M15: =ROUND(I15/VD_počet_měsíců_úžívání,2) -> 0 | N15: =IF(C15="počet osob", CEILING(K15/'vstupní data'!$AJ$31/VD_počet_měsíců_úžívání*($O$7*12), 10), ROUNDUP(K15/VD_počet_měsíců_úžívání, -1)) -> 0 | O15: =CEILING(K15/'vstupní data'!$AJ$31/VD_počet_měsíců_úžívání*($O$7*12),10) -> 0 | P15: =ROUND(MAX(0,I15/VD_počet_měsíců_úžívání-IF($P$7>0,L15/VD_počet_měsíců_úžívání*1.05,L15/VD_počet_měsíců_úžívání*0.95)),0) -> 0 | Q15: 0
A16: =Faktury!A9 -> Ohřev teplé vody (TUV) | C16: =Faktury!C9 -> 0 | D16: =Faktury!D9 -> 0 | E16: =Faktury!E9 -> 0 | F16: =Faktury!F9 -> 0 | G16: =Faktury!G9 -> 0 | H16: =Faktury!H9 -> 0 | I16: ='Vyúčtování byt - 1.část'!J16 -> 0 | J16: =Faktury!I9 -> 0 | K16: =IF(J16=0,0,J16*(100+Q16)/100) -> 0 | L16: ='Vyúčtování byt - 1.část'!K16 -> 0 | M16: =ROUND(I16/VD_počet_měsíců_úžívání,2) -> 0 | N16: =IF(C16="počet osob", CEILING(K16/'vstupní data'!$AJ$31/VD_počet_měsíců_úžívání*($O$7*12), 10), ROUNDUP(K16/VD_počet_měsíců_úžívání, -1)) -> 0 | O16: =CEILING(K16/'vstupní data'!$AJ$31/VD_počet_měsíců_úžívání*($O$7*12),10) -> 0 | P16: =ROUND(MAX(0,I16/VD_počet_měsíců_úžívání-IF($P$7>0,L16/VD_počet_měsíců_úžívání*1.05,L16/VD_počet_měsíců_úžívání*0.95)),0) -> 0 | Q16: 0
A17: =Faktury!A2 -> Fond oprav | C17: =Faktury!C2 -> nevyúčtovává se | D17: =Faktury!D2 -> 0 | E17: =Faktury!E2 -> 0 | F17: =Faktury!F2 -> 0 | G17: =Faktury!G2 -> 0 | H17: =Faktury!H2 -> 0 | I17: ='Vyúčtování byt - 1.část'!J17 -> 0 | J17: =Faktury!I2 -> 0 | K17: =IF(J17=0,0,J17*(100+Q17)/100) -> 0 | L17: ='Vyúčtování byt - 1.část'!K17 -> 0 | M17: =ROUND(I17/VD_počet_měsíců_úžívání,2) -> 0 | N17: =IF(C17="počet osob", CEILING(K17/'vstupní data'!$AJ$31/VD_počet_měsíců_úžívání*($O$7*12), 10), ROUNDUP(K17/VD_počet_měsíců_úžívání, -1)) -> 0 | O17: =CEILING(K17/'vstupní data'!$AJ$31/VD_počet_měsíců_úžívání*($O$7*12),10) -> 0 | P17: =ROUND(MAX(0,I17/VD_počet_měsíců_úžívání-IF($P$7>0,L17/VD_počet_měsíců_úžívání*1.05,L17/VD_počet_měsíců_úžívání*0.95)),0) -> 0 | Q17: 0
A18: =Faktury!A3 -> Studená voda | C18: =Faktury!C3 -> počet osob | D18: =Faktury!D3 -> 100 | E18: =Faktury!E3 -> 75347.33 | F18: =Faktury!F3 -> 868 | G18: =Faktury!G3 -> 86.81 | H18: =Faktury!H3 -> 35 | I18: ='Vyúčtování byt - 1.část'!J18 -> 8280 | J18: =Faktury!I3 -> 9618.74 | K18: =IF(J18=0,0,J18*(100+Q18)/100) -> 9618.74 | L18: ='Vyúčtování byt - 1.část'!K18 -> -1338.74 | M18: =ROUND(I18/VD_počet_měsíců_úžívání,2) -> 690 | N18: =IF(C18="počet osob", CEILING(K18/'vstupní data'!$AJ$31/VD_počet_měsíců_úžívání*($O$7*12), 10), ROUNDUP(K18/VD_počet_měsíců_úžívání, -1)) -> 810 | O18: =CEILING(K18/'vstupní data'!$AJ$31/VD_počet_měsíců_úžívání*($O$7*12),10) -> 810 | P18: =ROUND(MAX(0,I18/VD_počet_měsíců_úžívání-IF($P$7>0,L18/VD_počet_měsíců_úžívání*1.05,L18/VD_počet_měsíců_úžívání*0.95)),0) -> 807 | Q18: 0
A19: =Faktury!A19 -> Ostatní náklady - UPC | C19: =Faktury!C19 -> na byt | D19: =Faktury!D19 -> 100 | E19: =Faktury!E19 -> 57999 | F19: =Faktury!F19 -> 9 | G19: =Faktury!G19 -> 6444.33 | H19: =Faktury!H19 -> 0 | I19: ='Vyúčtování byt - 1.část'!J19 -> 0 | J19: =Faktury!I19 -> 0 | K19: =IF(J19=0,0,J19*(100+Q19)/100) -> 0 | L19: ='Vyúčtování byt - 1.část'!K19 -> 0 | M19: =ROUND(I19/VD_počet_měsíců_úžívání,2) -> 0 | N19: =IF(C19="počet osob", CEILING(K19/'vstupní data'!$AJ$31/VD_počet_měsíců_úžívání*($O$7*12), 10), ROUNDUP(K19/VD_počet_měsíců_úžívání, -1)) -> 0 | O19: =CEILING(K19/'vstupní data'!$AJ$31/VD_počet_měsíců_úžívání*($O$7*12),10) -> 0 | P19: =ROUND(MAX(0,I19/VD_počet_měsíců_úžívání-IF($P$7>0,L19/VD_počet_měsíců_úžívání*1.05,L19/VD_počet_měsíců_úžívání*0.95)),0) -> 0 | Q19: 0
A20: =Faktury!A18 -> Ostatní náklady (garáž a sklepy) | C20: =Faktury!C18 -> 0 | D20: =Faktury!D18 -> 0 | E20: =Faktury!E18 -> 0 | F20: =Faktury!F18 -> 0 | G20: =Faktury!G18 -> 0 | H20: =Faktury!H18 -> 0 | I20: ='Vyúčtování byt - 1.část'!J20 -> 0 | J20: =Faktury!I18 -> 0 | K20: =IF(J20=0,0,J20*(100+Q20)/100) -> 0 | L20: ='Vyúčtování byt - 1.část'!K20 -> 0 | M20: =ROUND(I20/VD_počet_měsíců_úžívání,2) -> 0 | N20: =IF(C20="počet osob", CEILING(K20/'vstupní data'!$AJ$31/VD_počet_měsíců_úžívání*($O$7*12), 10), ROUNDUP(K20/VD_počet_měsíců_úžívání, -1)) -> 0 | O20: =CEILING(K20/'vstupní data'!$AJ$31/VD_počet_měsíců_úžívání*($O$7*12),10) -> 0 | P20: =ROUND(MAX(0,I20/VD_počet_měsíců_úžívání-IF($P$7>0,L20/VD_počet_měsíců_úžívání*1.05,L20/VD_počet_měsíců_úžívání*0.95)),0) -> 0 | Q20: 0
A21: =Faktury!A10 -> 0 | C21: =Faktury!C10 -> 0 | D21: =Faktury!D10 -> 0 | E21: =Faktury!E10 -> 0 | F21: =Faktury!F10 -> 0 | G21: =Faktury!G10 -> 0 | H21: =Faktury!H10 -> 0 | I21: ='Vyúčtování byt - 1.část'!J21 -> 0 | J21: =Faktury!I10 -> 0 | K21: =IF(J21=0,0,J21*(100+Q21)/100) -> 0 | L21: ='Vyúčtování byt - 1.část'!K21 -> 0 | M21: =ROUND(I21/VD_počet_měsíců_úžívání,2) -> 0 | N21: =IF(C21="počet osob", CEILING(K21/'vstupní data'!$AJ$31/VD_počet_měsíců_úžívání*($O$7*12), 10), ROUNDUP(K21/VD_počet_měsíců_úžívání, -1)) -> 0 | O21: =CEILING(K21/'vstupní data'!$AJ$31/VD_počet_měsíců_úžívání*($O$7*12),10) -> 0 | P21: =ROUND(MAX(0,I21/VD_počet_měsíců_úžívání-IF($P$7>0,L21/VD_počet_měsíců_úžívání*1.05,L21/VD_počet_měsíců_úžívání*0.95)),0) -> 0 | Q21: 0
A22: =Faktury!A8 -> Záloha na teplo | C22: =Faktury!C8 -> 0 | D22: =Faktury!D8 -> 0 | E22: =Faktury!E8 -> 0 | F22: =Faktury!F8 -> 0 | G22: =Faktury!G8 -> 0 | H22: =Faktury!H8 -> 0 | I22: ='Vyúčtování byt - 1.část'!J22 -> 0 | J22: =Faktury!I8 -> 0 | K22: =IF(J22=0,0,J22*(100+Q22)/100) -> 0 | L22: ='Vyúčtování byt - 1.část'!K22 -> 0 | M22: =ROUND(I22/VD_počet_měsíců_úžívání,2) -> 0 | N22: =IF(C22="počet osob", CEILING(K22/'vstupní data'!$AJ$31/VD_počet_měsíců_úžívání*($O$7*12), 10), ROUNDUP(K22/VD_počet_měsíců_úžívání, -1)) -> 0 | O22: =CEILING(K22/'vstupní data'!$AJ$31/VD_počet_měsíců_úžívání*($O$7*12),10) -> 0 | P22: =ROUND(MAX(0,I22/VD_počet_měsíců_úžívání-IF($P$7>0,L22/VD_počet_měsíců_úžívání*1.05,L22/VD_počet_měsíců_úžívání*0.95)),0) -> 0 | Q22: 0
A23: =Faktury!A16 -> Poplatek za psa | C23: =Faktury!C16 -> 0 | D23: =Faktury!D16 -> 0 | E23: =Faktury!E16 -> 0 | F23: =Faktury!F16 -> 0 | G23: =Faktury!G16 -> 0 | H23: =Faktury!H16 -> 0 | I23: ='Vyúčtování byt - 1.část'!J23 -> 0 | J23: =Faktury!I16 -> 0 | K23: =IF(J23=0,0,J23*(100+Q23)/100) -> 0 | L23: ='Vyúčtování byt - 1.část'!K23 -> 0 | M23: =ROUND(I23/VD_počet_měsíců_úžívání,2) -> 0 | N23: =IF(C23="počet osob", CEILING(K23/'vstupní data'!$AJ$31/VD_počet_měsíců_úžívání*($O$7*12), 10), ROUNDUP(K23/VD_počet_měsíců_úžívání, -1)) -> 0 | O23: =CEILING(K23/'vstupní data'!$AJ$31/VD_počet_měsíců_úžívání*($O$7*12),10) -> 0 | P23: =ROUND(MAX(0,I23/VD_počet_měsíců_úžívání-IF($P$7>0,L23/VD_počet_měsíců_úžívání*1.05,L23/VD_počet_měsíců_úžívání*0.95)),0) -> 0 | Q23: 0
A24: =Faktury!A22 -> Spořící účet | C24: =Faktury!C22 -> nevyúčtovává se | D24: =Faktury!D22 -> 0 | E24: =Faktury!E22 -> 0 | F24: =Faktury!F22 -> 0 | G24: =Faktury!G22 -> 0 | H24: =Faktury!H22 -> 0 | I24: ='Vyúčtování byt - 1.část'!J24 -> 0 | J24: =Faktury!I22 -> 0 | K24: =IF(J24=0,0,J24*(100+Q24)/100) -> 0 | L24: ='Vyúčtování byt - 1.část'!K24 -> 0 | M24: =ROUND(I24/VD_počet_měsíců_úžívání,2) -> 0 | N24: =IF(C24="počet osob", CEILING(K24/'vstupní data'!$AJ$31/VD_počet_měsíců_úžívání*($O$7*12), 10), ROUNDUP(K24/VD_počet_měsíců_úžívání, -1)) -> 0 | O24: =CEILING(K24/'vstupní data'!$AJ$31/VD_počet_měsíců_úžívání*($O$7*12),10) -> 0 | P24: =ROUND(MAX(0,I24/VD_počet_měsíců_úžívání-IF($P$7>0,L24/VD_počet_měsíců_úžívání*1.05,L24/VD_počet_měsíců_úžívání*0.95)),0) -> 0 | Q24: 0
A25: =Faktury!A23 -> 0 | C25: =Faktury!C23 -> 0 | D25: =Faktury!D23 -> 0 | E25: =Faktury!E23 -> 0 | F25: =Faktury!F23 -> 0 | G25: =Faktury!G23 -> 0 | H25: =Faktury!H23 -> 0 | I25: ='Vyúčtování byt - 1.část'!J25 -> 0 | J25: =Faktury!I23 -> 0 | K25: =IF(J25=0,0,J25*(100+Q25)/100) -> 0 | L25: ='Vyúčtování byt - 1.část'!K25 -> 0 | M25: =ROUND(I25/VD_počet_měsíců_úžívání,2) -> 0 | N25: =IF(C25="počet osob", CEILING(K25/'vstupní data'!$AJ$31/VD_počet_měsíců_úžívání*($O$7*12), 10), ROUNDUP(K25/VD_počet_měsíců_úžívání, -1)) -> 0 | O25: =CEILING(K25/'vstupní data'!$AJ$31/VD_počet_měsíců_úžívání*($O$7*12),10) -> 0 | P25: =ROUND(MAX(0,I25/VD_počet_měsíců_úžívání-IF($P$7>0,L25/VD_počet_měsíců_úžívání*1.05,L25/VD_počet_měsíců_úžívání*0.95)),0) -> 0 | Q25: 0
A26: =Faktury!A15 -> Mzdové náklady | C26: =Faktury!C15 -> 0 | D26: =Faktury!D15 -> 0 | E26: =Faktury!E15 -> 0 | F26: =Faktury!F15 -> 0 | G26: =Faktury!G15 -> 0 | H26: =Faktury!H15 -> 0 | I26: ='Vyúčtování byt - 1.část'!J26 -> 0 | J26: =Faktury!I15 -> 0 | K26: =IF(J26=0,0,J26*(100+Q26)/100) -> 0 | L26: ='Vyúčtování byt - 1.část'!K26 -> 0 | M26: =ROUND(I26/VD_počet_měsíců_úžívání,2) -> 0 | N26: =IF(C26="počet osob", CEILING(K26/'vstupní data'!$AJ$31/VD_počet_měsíců_úžívání*($O$7*12), 10), ROUNDUP(K26/VD_počet_měsíců_úžívání, -1)) -> 0 | O26: =CEILING(K26/'vstupní data'!$AJ$31/VD_počet_měsíců_úžívání*($O$7*12),10) -> 0 | P26: =ROUND(MAX(0,I26/VD_počet_měsíců_úžívání-IF($P$7>0,L26/VD_počet_měsíců_úžívání*1.05,L26/VD_počet_měsíců_úžívání*0.95)),0) -> 0 | Q26: 0
A27: =Faktury!A13 -> Ostatní nájemné | C27: =Faktury!C13 -> 0 | D27: =Faktury!D13 -> 0 | E27: =Faktury!E13 -> 0 | F27: =Faktury!F13 -> 0 | G27: =Faktury!G13 -> 0 | H27: =Faktury!H13 -> 0 | I27: ='Vyúčtování byt - 1.část'!J27 -> 0 | J27: =Faktury!I13 -> 0 | K27: =IF(J27=0,0,J27*(100+Q27)/100) -> 0 | L27: ='Vyúčtování byt - 1.část'!K27 -> 0 | M27: =ROUND(I27/VD_počet_měsíců_úžívání,2) -> 0 | N27: =IF(C27="počet osob", CEILING(K27/'vstupní data'!$AJ$31/VD_počet_měsíců_úžívání*($O$7*12), 10), ROUNDUP(K27/VD_počet_měsíců_úžívání, -1)) -> 0 | O27: =CEILING(K27/'vstupní data'!$AJ$31/VD_počet_měsíců_úžívání*($O$7*12),10) -> 0 | P27: =ROUND(MAX(0,I27/VD_počet_měsíců_úžívání-IF($P$7>0,L27/VD_počet_měsíců_úžívání*1.05,L27/VD_počet_měsíců_úžívání*0.95)),0) -> 0 | Q27: 0
A28: =Faktury!A14 -> Ostatní služby | C28: =Faktury!C14 -> 0 | D28: =Faktury!D14 -> 0 | E28: =Faktury!E14 -> 0 | F28: =Faktury!F14 -> 0 | G28: =Faktury!G14 -> 0 | H28: =Faktury!H14 -> 0 | I28: ='Vyúčtování byt - 1.část'!J28 -> 0 | J28: =Faktury!I14 -> 0 | K28: =IF(J28=0,0,J28*(100+Q28)/100) -> 0 | L28: ='Vyúčtování byt - 1.část'!K28 -> 0 | M28: =ROUND(I28/VD_počet_měsíců_úžívání,2) -> 0 | N28: =IF(C28="počet osob", CEILING(K28/'vstupní data'!$AJ$31/VD_počet_měsíců_úžívání*($O$7*12), 10), ROUNDUP(K28/VD_počet_měsíců_úžívání, -1)) -> 0 | O28: =CEILING(K28/'vstupní data'!$AJ$31/VD_počet_měsíců_úžívání*($O$7*12),10) -> 0 | P28: =ROUND(MAX(0,I28/VD_počet_měsíců_úžívání-IF($P$7>0,L28/VD_počet_měsíců_úžívání*1.05,L28/VD_počet_měsíců_úžívání*0.95)),0) -> 0 | Q28: 0
A29: =Faktury!A11 -> Správa domu | C29: =Faktury!C11 -> na byt | D29: =Faktury!D11 -> 100 | E29: =Faktury!E11 -> 42566 | F29: =Faktury!F11 -> 19 | G29: =Faktury!G11 -> 2240.32 | H29: =Faktury!H11 -> 1 | I29: ='Vyúčtování byt - 1.část'!J29 -> 1440 | J29: =Faktury!I11 -> 2240.32 | K29: =IF(J29=0,0,J29*(100+Q29)/100) -> 2240.32 | L29: ='Vyúčtování byt - 1.část'!K29 -> -800.32 | M29: =ROUND(I29/VD_počet_měsíců_úžívání,2) -> 120 | N29: =IF(C29="počet osob", CEILING(K29/'vstupní data'!$AJ$31/VD_počet_měsíců_úžívání*($O$7*12), 10), ROUNDUP(K29/VD_počet_měsíců_úžívání, -1)) -> 190 | O29: =CEILING(K29/'vstupní data'!$AJ$31/VD_počet_měsíců_úžívání*($O$7*12),10) -> 190 | P29: =ROUND(MAX(0,I29/VD_počet_měsíců_úžívání-IF($P$7>0,L29/VD_počet_měsíců_úžívání*1.05,L29/VD_počet_měsíců_úžívání*0.95)),0) -> 190 | Q29: 0
A30: Celkem náklady na odběrná místa | E30: =SUM(E10:E29) -> 261494.22 | G30: Celkem vyúčtování: | I30: =SUM(I10:I29) -> 13800 | J30: =SUM(J10:J29) -> 16252.71 | K30: =SUM(K10:K29) -> 16252.71 | M30: =SUM(M10:M29) -> 1150 | N30: =SUM(N10:N29) -> 1380 | P30: =SUM(P10:P29) -> 1364
G31: Měsíčně včetně fondu oprav | M31: =M30+A36/VD_počet_měsíců_úžívání -> 3813 | N31: =N30+A36/VD_počet_měsíců_úžívání -> 4043 | O31: Rozdíl měsíčně | P31: =ROUND(P30-M30,0) -> 214 | Q31: * mění se pouze položky této barvy zbytek systém počítá sám, navýšení % nastavujeme až do akceptovatelného preplatku
O32: Kontrola | P32: =P31-P7 -> 209
A33: Pevné platby
A34: ='Vyúčtování byt - 1.část'!A35 -> Fond oprav
A35: Celkem za rok
A36: ='Vyúčtování byt - 1.část'!B35 -> 31956 | K36: KONTROLA
A37: Výsledek vyúčtování | K37: Zálohy před změnou | M37: =M31 -> 3813 | N37: *udělat kontrolu s OS zda sedí
A38: =ROUND('Vyúčtování byt - 1.část'!K31,0) -> -2453 | K38: Záloha po změně | M38: =N31 -> 4043
K39: Rozdíl měsíčně | M39: =M38-M37 -> 230 | N39: =M39*VD_počet_měsíců_úžívání+'Vyúčtování byt - 1.část'!VB_preplatky_celkem -> 307 | O39: *kontrola zda vychází stejněj jako budoucí přeplatek
K40: Náklad za poslední vyúčtování | M40: =J30 -> 16252.71
K41: Teoretický náklad po změně | M41: =N30*VD_počet_měsíců_úžívání -> 16560
...

Sheet Seznam
A1: MENU
A2: VÝSTUPY | B2: MĚŘIDLA A DATA | C2: EVIDENCE | D2: EXPORT | E2: KONTROLA
A3: Vstupní data | B3: Vodoměry TUV | C3: Evidence | D3: Export send mail | E3: Výpočet vyúčtování
A4: Vyúčtování | B4: Vodoměry SV | C4: Úhrady | D4: Bytové domy
A5: Příjem SVJ včetně výdajů | B5: Teplo | C5: Přeplatky a nedoplatky | D5: Odečty formulář
A6: Příjem SVJ bez výdajů | B6: Elektroměry | C6: Předpisy - výpočet
A7: Náklady za dům | B7: Výtahy
A8: Faktury | B8: Počet osob
A9: Rozpočet domu | B9: Předpisy po měsící
A10: Parametry | B10: Faktury za služby

Sheet Vyúčtování byt - 1.část
C1: =IF('vstupní data'!B34="AdminReal, s.r.o.","AdminReal s.r.o., Veveří 2581/102 , 616 00 Brno, IČO 02827476, Zapsáno KS v Brně, oddíl C, vložka 82606","BrnoReal s.r.o., Veveří 2581/102 , 616 00 Brno, IČO 14423537, Zapsáno KS v Brně, oddíl C, vložka 128255") -> AdminReal s.r.o., Veveří 2581/102 , 616 00 Brno, IČO 02827476, Zapsáno KS v Brně, oddíl C, vložka 82606 | J1: =IF('vstupní data'!$B$34="BrnoReal, s.r.o.",'vstupní data'!$B$60,'vstupní data'!$B$59) -> #VALUE!
A2: ='vstupní data'!B5 -> Martin Klíma | N2: MENU
A3: adresa společenství: | C3: =dum_adresa -> Zborovská 939/2, Žabovřesky, 616 00 Brno | F3: bankovní spojení člena: | H3: ='vstupní data'!B7 -> 8308679001/5500 | J3: č. prostoru: | K3: ='vstupní data'!B4 -> Byt č. 939/01
A4: bankovní spojení společenství: | C4: ='vstupní data'!B35 -> 2100704207/2010 | E4: variabilní symbol pro platbu nedoplatku: | H4: ='vstupní data'!B6 -> 1093900019 | J4: zůčtovací období: | K4: =VLOOKUP(BYT,Evidence!$A:$Z,18,0) -> 1.1.2024 - 31.12.2024
A6: =("Vyúčtování služeb: "&'vstupní data'!B12&"") -> Vyúčtování služeb: 2024
E8: Odběrné místo (dům) | H8: Uživatel
A9: Položka | B9: Sloupec1 | C9: Jednotka | D9: Podíl | E9: Náklad | F9: Jednotek | G9: Kč/jedn | H9: Jednotek2 | I9: Náklad2 | J9: Záloha | K9: Přeplatky|nedoplatky
A10: =Faktury!A4 -> Elektrická energie (společné prostory) | C10: =Faktury!C4 -> počet osob | D10: =Faktury!D4 -> 100 | E10: =Faktury!E4 -> 8663.77 | F10: =Faktury!F4 -> 439 | G10: =Faktury!G4 -> 19.74 | H10: =Faktury!H4 -> 48 | I10: =Faktury!I4 -> 947.52 | J10: =Faktury!J4 -> 540 | K10: =Faktury!K4 -> -407.52
A11: =Faktury!A5 -> Úklid bytového domu | C11: =Faktury!C5 -> počet osob | D11: =Faktury!D5 -> 100 | E11: =Faktury!E5 -> 25800 | F11: =Faktury!F5 -> 439 | G11: =Faktury!G5 -> 58.77 | H11: =Faktury!H5 -> 48 | I11: =Faktury!I5 -> 2820.96 | J11: =Faktury!J5 -> 3000 | K11: =Faktury!K5 -> 179.04
A12: =Faktury!A6 -> Komíny | C12: =Faktury!C6 -> komín | D12: =Faktury!D6 -> 100 | E12: =Faktury!E6 -> 7502 | F12: =Faktury!F6 -> 12 | G12: =Faktury!G6 -> 625.17 | H12: =Faktury!H6 -> 1 | I12: =Faktury!I6 -> 625.17 | J12: =Faktury!J6 -> 540 | K12: =Faktury!K6 -> -85.17
A13: =Faktury!A7 -> Pravidelná údržba výtah | C13: =Faktury!C7 -> počet osob | D13: =Faktury!D7 -> 100 | E13: =Faktury!E7 -> 43616.12 | F13: =Faktury!F7 -> 307 | G13: =Faktury!G7 -> 142.07 | H13: =Faktury!H7 -> 0 | I13: =Faktury!I7 -> 0 | J13: =Faktury!J7 -> 0 | K13: =Faktury!K7 -> 0
A14: =Faktury!A17 -> Fond oprav nebytových prostor | C14: =Faktury!C17 -> 0 | D14: =Faktury!D17 -> 0 | E14: =Faktury!E17 -> 0 | F14: =Faktury!F17 -> 0 | G14: =Faktury!G17 -> 0 | H14: =Faktury!H17 -> 0 | I14: =Faktury!I17 -> 0 | J14: =Faktury!J17 -> 0 | K14: =Faktury!K17 -> 0
A15: =Faktury!A12 -> Pojištění domu | C15: =Faktury!C12 -> 0 | D15: =Faktury!D12 -> 0 | E15: =Faktury!E12 -> 0 | F15: =Faktury!F12 -> 0 | G15: =Faktury!G12 -> 0 | H15: =Faktury!H12 -> 0 | I15: =Faktury!I12 -> 0 | J15: =Faktury!J12 -> 0 | K15: =Faktury!K12 -> 0
A16: =Faktury!A9 -> Ohřev teplé vody (TUV) | C16: =Faktury!C9 -> 0 | D16: =Faktury!D9 -> 0 | E16: =Faktury!E9 -> 0 | F16: =Faktury!F9 -> 0 | G16: =Faktury!G9 -> 0 | H16: =Faktury!H9 -> 0 | I16: =Faktury!I9 -> 0 | J16: =Faktury!J9 -> 0 | K16: =Faktury!K9 -> 0
A17: =Faktury!A2 -> Fond oprav | C17: =Faktury!C2 -> nevyúčtovává se | D17: =Faktury!D2 -> 0 | E17: =Faktury!E2 -> 0 | F17: =Faktury!F2 -> 0 | G17: =Faktury!G2 -> 0 | H17: =Faktury!H2 -> 0 | I17: =Faktury!I2 -> 0 | J17: =Faktury!J2 -> 0 | K17: =Faktury!K2 -> 0
A18: =Faktury!A3 -> Studená voda | C18: =Faktury!C3 -> počet osob | D18: =Faktury!D3 -> 100 | E18: =Faktury!E3 -> 75347.33 | F18: =Faktury!F3 -> 868 | G18: =Faktury!G3 -> 86.81 | H18: =Faktury!H3 -> 35 | I18: =Faktury!I3 -> 9618.74 | J18: =Faktury!J3 -> 8280 | K18: =Faktury!K3 -> -1338.74
A19: =Faktury!A19 -> Ostatní náklady - UPC | C19: =Faktury!C19 -> na byt | D19: =Faktury!D19 -> 100 | E19: =Faktury!E19 -> 57999 | F19: =Faktury!F19 -> 9 | G19: =Faktury!G19 -> 6444.33 | H19: =Faktury!H19 -> 0 | I19: =Faktury!I19 -> 0 | J19: =Faktury!J19 -> 0 | K19: =Faktury!K19 -> 0
A20: =Faktury!A18 -> Ostatní náklady (garáž a sklepy) | C20: =Faktury!C18 -> 0 | D20: =Faktury!D18 -> 0 | E20: =Faktury!E18 -> 0 | F20: =Faktury!F18 -> 0 | G20: =Faktury!G18 -> 0 | H20: =Faktury!H18 -> 0 | I20: =Faktury!I18 -> 0 | J20: =Faktury!J18 -> 0 | K20: =Faktury!K18 -> 0
A21: =Faktury!A10 -> 0 | C21: =Faktury!C10 -> 0 | D21: =Faktury!D10 -> 0 | E21: =Faktury!E10 -> 0 | F21: =Faktury!F10 -> 0 | G21: =Faktury!G10 -> 0 | H21: =Faktury!H10 -> 0 | I21: =Faktury!I10 -> 0 | J21: =Faktury!J10 -> 0 | K21: =Faktury!K10 -> 0
A22: =Faktury!A8 -> Záloha na teplo | C22: =Faktury!C8 -> 0 | D22: =Faktury!D8 -> 0 | E22: =Faktury!E8 -> 0 | F22: =Faktury!F8 -> 0 | G22: =Faktury!G8 -> 0 | H22: =Faktury!H8 -> 0 | I22: =Faktury!I8 -> 0 | J22: =Faktury!J8 -> 0 | K22: =Faktury!K8 -> 0
A23: =Faktury!A16 -> Poplatek za psa | C23: =Faktury!C16 -> 0 | D23: =Faktury!D16 -> 0 | E23: =Faktury!E16 -> 0 | F23: =Faktury!F16 -> 0 | G23: =Faktury!G16 -> 0 | H23: =Faktury!H16 -> 0 | I23: =Faktury!I16 -> 0 | J23: =Faktury!J16 -> 0 | K23: =Faktury!K16 -> 0
A24: =Faktury!A22 -> Spořící účet | C24: =Faktury!C22 -> nevyúčtovává se | D24: =Faktury!D22 -> 0 | E24: =Faktury!E22 -> 0 | F24: =Faktury!F22 -> 0 | G24: =Faktury!G22 -> 0 | H24: =Faktury!H22 -> 0 | I24: =Faktury!I22 -> 0 | J24: =Faktury!J22 -> 0 | K24: =Faktury!K22 -> 0
A25: =Faktury!A23 -> 0 | C25: =Faktury!C23 -> 0 | D25: =Faktury!D23 -> 0 | E25: =Faktury!E23 -> 0 | F25: =Faktury!F23 -> 0 | G25: =Faktury!G23 -> 0 | H25: =Faktury!H23 -> 0 | I25: =Faktury!I23 -> 0 | J25: =Faktury!J23 -> 0 | K25: =Faktury!K23 -> 0
A26: =Faktury!A15 -> Mzdové náklady | C26: =Faktury!C15 -> 0 | D26: =Faktury!D15 -> 0 | E26: =Faktury!E15 -> 0 | F26: =Faktury!F15 -> 0 | G26: =Faktury!G15 -> 0 | H26: =Faktury!H15 -> 0 | I26: =Faktury!I15 -> 0 | J26: =Faktury!J15 -> 0 | K26: =Faktury!K15 -> 0
A27: =Faktury!A13 -> Ostatní nájemné | C27: =Faktury!C13 -> 0 | D27: =Faktury!D13 -> 0 | E27: =Faktury!E13 -> 0 | F27: =Faktury!F13 -> 0 | G27: =Faktury!G13 -> 0 | H27: =Faktury!H13 -> 0 | I27: =Faktury!I13 -> 0 | J27: =Faktury!J13 -> 0 | K27: =Faktury!K13 -> 0
A28: =Faktury!A14 -> Ostatní služby | C28: =Faktury!C14 -> 0 | D28: =Faktury!D14 -> 0 | E28: =Faktury!E14 -> 0 | F28: =Faktury!F14 -> 0 | G28: =Faktury!G14 -> 0 | H28: =Faktury!H14 -> 0 | I28: =Faktury!I14 -> 0 | J28: =Faktury!J14 -> 0 | K28: =Faktury!K14 -> 0
A29: =Faktury!A11 -> Správa domu | C29: =Faktury!C11 -> na byt | D29: =Faktury!D11 -> 100 | E29: =Faktury!E11 -> 42566 | F29: =Faktury!F11 -> 19 | G29: =Faktury!G11 -> 2240.32 | H29: =Faktury!H11 -> 1 | I29: =Faktury!I11 -> 2240.32 | J29: =Faktury!J11 -> 1440 | K29: =Faktury!K11 -> -800.32
A30: =Faktury!A21 -> Ostatní služby 2 | C30: =Faktury!C21 -> 0 | D30: =Faktury!D21 -> 0 | E30: =Faktury!E21 -> 0 | F30: =Faktury!F21 -> 0 | G30: =Faktury!G21 -> 0 | H30: =Faktury!H21 -> 0 | I30: =Faktury!I21 -> 0 | J30: =Faktury!J21 -> 0 | K30: =Faktury!K21 -> 0
A31: Celkem náklady na odběrná místa | E31: =SUM(E10:E30) -> 261494.22 | G31: Celkem vyúčtování: | I31: =SUM(I10:I30) -> 16252.71 | J31: =SUM(J10:J30) -> 13800 | K31: =SUM(K10:K30) -> -2452.71
C32: =IF(ExcelMacroData!C15=TRUE,_xlfn.IMAGE(ExcelMacroData!C16),"") -> #VALUE! | G32: =IF(K32<0,"Nedoplatek v účtovaném období",IF(K32>0,"Přeplatek v účtovaném období",IF(K32=0,"Není evidován v účtovaném období přeplatek ani nedoplatek"))) -> Není evidován v účtovaném období přeplatek ani nedoplatek | K32: =VD_přeplatek_aktuální_rok -> 0
G33: =IF(K33<0,"Nedoplatek v minulém období",IF(K33>0,"Přeplatek v minulém období",IF(K33=0,"Není evidován v minulém období přeplatek ani nedoplatek"))) -> Není evidován v minulém období přeplatek ani nedoplatek | K33: =VLOOKUP(BYT,'Přeplatky nedoplatky'!$A:$E,5,0) -> 0
A34: Pevné platby | B34: Celkem za rok | G34: =IF('Vyúčtování byt - 1.část'!K34<0,"NEDOPLATEK CELKEM",IF('Vyúčtování byt - 1.část'!K34>0,"PŘEPLATEK CELKEM",IF('Vyúčtování byt - 1.část'!K34=0,"Nemáte přeplatek ani nedoplatek"))) -> NEDOPLATEK CELKEM | K34: =ROUND(K31+K32+K33,0) -> -2453
A35: =INDEX(Faktury!A2:A53,MATCH("*Fond*",Faktury!A2:A53,0)) -> Fond oprav | B35: ='vstupní data'!R17 -> 31956 | E35: =IF(VD_účet_vlastníka=0,(IF('vstupní data'!C11<0,"Nedoplatek uhraďte na účet číslo: "&VD_číslo_účtu_SVJ&", variabilní symbol "&VD_VS&"",IF('vstupní data'!C11>0,"Přeplatek Vám bude vyplacen poštovní poukázkou",IF('vstupní data'!C11=0,"""Nemáte žádný přeplatek ani nedoplatek")))),IF('vstupní data'!C11<0,"Nedoplatek uhraďte na účet číslo: "&VD_číslo_účtu_SVJ&", variabilní symbol "&VD_VS&"",IF('vstupní data'!C11>0,"Přeplatek Vám bude vyplacen na číslo účtu "&VD_účet_vlastníka&"",IF('vstupní data'!C11=0,"Nemáte žádný přeplatek ani nedoplatek")))) -> Nedoplatek uhraďte na účet číslo: 2100704207/2010, variabilní symbol 1093900019
A37: ="Přehled úhrad za rok "&'vstupní data'!B12&"" -> Přehled úhrad za rok 2024
A38: ="1/"&'vstupní data'!$B$12&"" -> 1/2024 | B38: ="2/"&'vstupní data'!$B$12&"" -> 2/2024 | C38: ="3/"&'vstupní data'!$B$12&"" -> 3/2024 | D38: ="4/"&'vstupní data'!$B$12&"" -> 4/2024 | E38: ="5/"&'vstupní data'!$B$12&"" -> 5/2024 | F38: ="6/"&'vstupní data'!$B$12&"" -> 6/2024 | G38: ="7/"&'vstupní data'!$B$12&"" -> 7/2024 | H38: ="8/"&'vstupní data'!$B$12&"" -> 8/2024 | I38: ="9/"&'vstupní data'!$B$12&"" -> 9/2024 | J38: ="10/"&'vstupní data'!$B$12&"" -> 10/2024 | K38: ="11/"&'vstupní data'!$B$12&"" -> 11/2024 | L38: ="12/"&'vstupní data'!$B$12&"" -> 12/2024
A39: ='vstupní data'!N19 -> 3813 | B39: ='vstupní data'!N20 -> 0 | C39: ='vstupní data'!N21 -> 7626 | D39: ='vstupní data'!N22 -> 3813 | E39: ='vstupní data'!N23 -> 0 | F39: ='vstupní data'!N24 -> 7626 | G39: ='vstupní data'!N25 -> 7626 | H39: ='vstupní data'!N26 -> 0 | I39: ='vstupní data'!N27 -> 0 | J39: ='vstupní data'!N28 -> 7626 | K39: ='vstupní data'!N29 -> 7626 | L39: ='vstupní data'!N30 -> 0
A40: ="Přehled předpisů za rok "&'vstupní data'!B12&"" -> Přehled předpisů za rok 2024
A41: ="1/"&'vstupní data'!$B$12&"" -> 1/2024 | B41: ="2/"&'vstupní data'!$B$12&"" -> 2/2024 | C41: ="3/"&'vstupní data'!$B$12&"" -> 3/2024 | D41: ="4/"&'vstupní data'!$B$12&"" -> 4/2024 | E41: ="5/"&'vstupní data'!$B$12&"" -> 5/2024 | F41: ="6/"&'vstupní data'!$B$12&"" -> 6/2024 | G41: ="7/"&'vstupní data'!$B$12&"" -> 7/2024 | H41: ="8/"&'vstupní data'!$B$12&"" -> 8/2024 | I41: ="9/"&'vstupní data'!$B$12&"" -> 9/2024 | J41: ="10/"&'vstupní data'!$B$12&"" -> 10/2024 | K41: ="11/"&'vstupní data'!$B$12&"" -> 11/2024 | L41: ="12/"&'vstupní data'!$B$12&"" -> 12/2024
A42: ='vstupní data'!Q19 -> 3813 | B42: ='vstupní data'!Q20 -> 3813 | C42: ='vstupní data'!Q21 -> 3813 | D42: ='vstupní data'!Q22 -> 3813 | E42: ='vstupní data'!Q23 -> 3813 | F42: ='vstupní data'!Q24 -> 3813 | G42: ='vstupní data'!Q25 -> 3813 | H42: ='vstupní data'!Q26 -> 3813 | I42: ='vstupní data'!Q27 -> 3813 | J42: ='vstupní data'!Q28 -> 3813 | K42: ='vstupní data'!Q29 -> 3813 | L42: ='vstupní data'!Q30 -> 3813
A43: =IF('vstupní data'!B11=0,"K úhradě za rok",IF('vstupní data'!B11<0,"Nedoplatek za rok celkem",IF('vstupní data'!B11>0,"Přeplatek za rok celkem",IF('vstupní data'!B11=0,"")))) -> K úhradě za rok | C43: ='vstupní data'!B11 -> 0
...

Sheet vstupní data
A1: Vstupní data
E2: Vysvětlivky polí(adres)
A3: Název - Bytový dům | B3: =C3 -> Společenství pro dům Zborovská 939/2, Brno | C3: Společenství pro dům Zborovská 939/2, Brno | D3: Zborovská 939/2, Žabovřesky, 616 00 Brno | E3: vp_ - vyhledávací pole - následuje jméno listu kde je
A4: Jednotka | B4: =Evidence!A2 -> Byt č. 939/01 | C4: =SUBSTITUTE(SUBSTITUTE(SUBSTITUTE(BYT," ","-"),"---","-"),"/","") -> Byt-č.-93901 | E4: VD_ vstupní dat, na začátku vždy zkratka listu
A5: Jméno | B5: =VLOOKUP(BYT,Evidence!$A:$Z,2,0) -> Martin Klíma | C5: =IF(D5="paní","Vážená","Vážený") -> Vážený | D5: =(IF(RIGHT(B5,1)="á","paní","pane")) -> pane | E5: =LEFT(VD_jméno,FIND(" ",B5)-1) -> Martin | F5: =TRIM(RIGHT(SUBSTITUTE(VD_jméno," ",REPT(" ",100)),100)) -> Klíma
A6: Variabilní symbol | B6: =VLOOKUP(BYT,Evidence!1:1048576,22,0) -> 1093900019 | C6: *vs je s devitkami na konci kvuli platbe
A7: bankovní spojení (účet) vlastníka bytu | B7: =VLOOKUP(BYT,Evidence!$A:$Z,11,0) -> 8308679001/5500 | L7: Úhrada dle delky vlastnictví | P7: Předpisy | R7: FO
A8: vyúčtovací období | B8: ="1.1."&'vstupní data'!$B$12&" - 1.12."&'vstupní data'!$B$12&"" -> 1.1.2024 - 1.12.2024 | F8: Platby záloh | H8: Předpis záloh | J8: Rozdíl | L8: Datum pro vypočet | M8: =VLOOKUP(BYT,Evidence!$A:$T,16,1) -> 1.1.2024 | N8: =VLOOKUP(BYT,Evidence!$A:$T,17,1) -> 31.12.2024
A9: Výsledek vyúčtování | F9: OD | G9: DO zbytek roku | H9: OD | I9: DO zbytek roku | J9: OD | K9: DO | L9: Převod na číslo sloupce | M9: =MONTH(M8) -> 1 | N9: =MONTH(N8) -> 12 | O9: 12 | P9: vzorec na změnu měsíců dle vlastnictví
A10: Přeplatek/nedoplatek z minulého období | B10: =VLOOKUP(BYT,'Přeplatky nedoplatky'!$A:$E,5,0) -> 0 | F10: =ADDRESS(MATCH('vstupní data'!$B$4,uhrady!A:A,0),2,4,1) -> B2 | G10: =ADDRESS((MATCH('vstupní data'!$B$4,uhrady!A:A,0)),(MATCH($B$15,'Předpis po mesici'!$B$2:$M$2,0)+1),4) -> M2 | H10: =ADDRESS(MATCH('vstupní data'!$B$4,'Předpis po mesici'!A:A,0),262,4,1) -> JB3 | I10: =ADDRESS((MATCH('vstupní data'!$B$4,'Předpis po mesici'!A:A,0)),(MATCH($B$15,'Předpis po mesici'!$JC$2:$JN$2,0)+262),4) -> JN3 | J10: =F11-H11 -> 0 | K10: =G11-I11 -> 0 | L10: Převod na písmeno sloupce | M10: =SUBSTITUTE(ADDRESS(1,M9+1,4),"1","") -> B | N10: =SUBSTITUTE(ADDRESS(1,N9+1,4),"1","") -> M | P10: =SUBSTITUTE(ADDRESS(1,M9+262,4),"1","") -> JC | Q10: =SUBSTITUTE(ADDRESS(1,N9+262,4),"1","") -> JN | R10: =SUBSTITUTE(ADDRESS(1,M9+79,4),"1","") -> CB | S10: =SUBSTITUTE(ADDRESS(1,N9+79,4),"1","") -> CM
A11: Přeplatky/nedoplatky v aktuálním roce | B11: =SUM(N19:N30)-SUM(Q19:Q30) -> 0 | C11: ='Vyúčtování byt - 1.část'!VB_preplatky_celkem -> -2453 | D11: =SUM(VD_přeplatek_z_minula+VD_přeplatek_aktuální_rok+C11) -> -2453 | F11: =_xlfn.IFNA(SUM(INDIRECT("'uhrady'!"&F10&":"&G10)),0) -> 45756 | G11: =LOOKUP(B4,uhrady!A:A,uhrady!N:N)-F11 -> 0 | H11: =_xlfn.IFNA(SUM(INDIRECT("'Předpis po mesici'!"&H10&":"&I10)),0) -> 45756 | I11: =LOOKUP(B4,'Předpis po mesici'!A:A,'Předpis po mesici'!JO:JO)-H11 -> 0 | L11: Pořet měsíců-pro kontrolu | M11: =N9-M9+1 -> 12
A12: Za rok | B12: 2024 | F12: Platba FO | L12: Řádek vybraneho bytu | M12: ="uhrady!"&ADDRESS(MATCH(BYT,uhrady!A:A,0),2,4,1) -> uhrady!B2 | N12: =ROW(INDIRECT(M12)) -> 2 | P12: ="'Předpis po mesici'!"&ADDRESS(MATCH(BYT,'Předpis po mesici'!A:A,0),2,4,1) -> 'Předpis po mesici'!B3 | Q12: =ROW(INDIRECT(P12)) -> 3 | R12: ="'Předpis po mesici'!"&ADDRESS(MATCH(BYT,'Předpis po mesici'!A:A,0),2,4,1) -> 'Předpis po mesici'!B3 | S12: =ROW(INDIRECT(R12)) -> 3
A13: Cena BVak | B13: 105,53 | F13: =ADDRESS(MATCH('vstupní data'!$B$4,'Předpis po mesici'!A:A,0),80,4,1) -> CB3 | G13: =ADDRESS((MATCH('vstupní data'!$B$4,'Předpis po mesici'!A:A,0)),(MATCH($B$15,'Předpis po mesici'!$B$2:$M$2,0)+79),4) -> CM3
C14: Zbylé měsíce | D14: Čas | F14: =_xlfn.IFNA(SUM(INDIRECT("'Předpis po mesici'!"&F13&":"&G13)),0) -> 31956 | G14: =LOOKUP(B4,'Předpis po mesici'!A:A,'Předpis po mesici'!CN:CN)-F14 -> 0 | L14: Adresa bunek pro součet | M14: =M10&$N12 -> B2 | N14: =N10&$N12 -> M2 | P14: =P10&$Q12 -> JC3 | Q14: =Q10&$Q12 -> JN3 | R14: =R10&$S12 -> CB3 | S14: =S10&$S12 -> CM3
A15: Počet měsíců (užíváno majitelem) | B15: =M11 -> 12 | C15: =12-B15 -> 0 | D15: první část roku | L15: Finální adresa pro součet | M15: ="uhrady!"&_xlfn.CONCAT(M14,":",N14) -> uhrady!B2:M2 | P15: ="'Předpis po mesici'!"&_xlfn.CONCAT(P14,":",Q14) -> 'Předpis po mesici'!JC3:JN3 | R15: ="'Předpis po mesici'!"&_xlfn.CONCAT(R14,":",S14) -> 'Předpis po mesici'!CB3:CM3
C16: První část roku | F16: Druhá část roku
A17: Počet jednotek | B17: 19 | C17: ="1.1."&'vstupní data'!B12&"" -> 1.1.2024 | D17: =EDATE(C17,B15)-1 -> 45657 | E17: =(""&'vstupní data'!C18&" - "&'vstupní data'!D18&"") -> 1.1.2024 - 31.12.2024 | F17: =EDATE(C17,B15) -> 45658 | G17: =EDATE(D17,C15) -> 45657 | H17: =(""&'vstupní data'!F18&" - "&'vstupní data'!G18&"") -> 1.1.2025 - 31.12.2024 | L17: Finání součet | M17: =SUM(INDIRECT(M15)) -> 45756 | P17: =SUM(INDIRECT(P15)) -> 45756 | R17: =SUM(INDIRECT(R15)) -> 31956
A18: Užitná plocha domu - celková | B18: 943 | C18: =""&TEXT(C17,"d.m.rrrr") -> 1.1.2024 | D18: =""&TEXT(D17,"d.m.rrrr") -> 31.12.2024 | F18: =""&TEXT(F17,"d.m.rrrr") -> 1.1.2025 | G18: =""&TEXT(G17,"d.m.rrrr") -> 31.12.2024 | M18: Úhrady | P18: Měsíc | Q18: Předpisy celkem | R18: Měsíc | S18: =("Služby "&'vstupní data'!B4&"") -> Služby Byt č. 939/01
A19: Užitná plocha domu - započitatelná | B19: 0 | L19: Platby jednotlivě | M19: 1 | N19: =IF(AND(M19>=$M$9,M19<=$O$9),VLOOKUP(BYT,uhrady!$A$2:$M$102,M19+1,FALSE),0) -> 3813 | P19: 1 | Q19: =IF(AND(P19>=$M$9,P19<=$O$9),VLOOKUP(BYT,'Předpis po mesici'!$A$3:$JQ$102,P19+262,FALSE),0) -> 3813 | R19: 1 | S19: =IF(AND(P19>=$M$9,P19<=$N$9),VLOOKUP(BYT,'Předpis po mesici'!$A$3:$JQ$102,P19+79,FALSE),0) -> 2663 | T19: =IF(AND(P19>=$M$9,P19<=$N$9),VLOOKUP(BYT,'Předpis po mesici'!$A$3:$JQ$102,P19+1,FALSE),0) -> 45 | U19: =IF(AND(P19>=$M$9,P19<=$N$9),VLOOKUP(BYT,'Předpis po mesici'!$A$3:$JQ$102,P19+14,FALSE),0) -> 250 | V19: =IF(AND(P19>=$M$9,P19<=$N$9),VLOOKUP(BYT,'Předpis po mesici'!$A$3:$JQ$102,P19+27,FALSE),0) -> 45 | W19: =IF(AND(P19>=$M$9,P19<=$N$9),VLOOKUP(BYT,'Předpis po mesici'!$A$3:$JQ$102,P19+40,FALSE),0) -> 0 | X19: =IF(AND(P19>=$M$9,P19<=$N$9),VLOOKUP(BYT,'Předpis po mesici'!$A$3:$JQ$102,P19+53,FALSE),0) -> 690 | Y19: =IF(AND(P19>=$M$9,P19<=$N$9),VLOOKUP(BYT,'Předpis po mesici'!$A$3:$JQ$102,P19+66,FALSE),0) -> 120 | Z19: =IF(AND(P19>=$M$9,P19<=$N$9),VLOOKUP(BYT,'Předpis po mesici'!$A$3:$JQ$102,P19+92,FALSE),0) -> 0 | AA19: =IF(AND(P19>=$M$9,P19<=$N$9),VLOOKUP(BYT,'Předpis po mesici'!$A$3:$JQ$102,P19+105,FALSE),0) -> 0 | AB19: =IF(AND(P19>=$M$9,P19<=$N$9),VLOOKUP(BYT,'Předpis po mesici'!$A$3:$JQ$102,P19+118,FALSE),0) -> 0 | AC19: =IF(AND(P19>=$M$9,P19<=$N$9),VLOOKUP(BYT,'Předpis po mesici'!$A$3:$JQ$102,P19+131,FALSE),0) -> 0 | AD19: =IF(AND(P19>=$M$9,P19<=$N$9),VLOOKUP(BYT,'Předpis po mesici'!$A$3:$JQ$102,P19+170,FALSE),0) -> 0 | AE19: =IF(AND(P19>=$M$9,P19<=$N$9),VLOOKUP(BYT,'Předpis po mesici'!$A$3:$JQ$102,P19+183,FALSE),0) -> 0 | AF19: =IF(AND(P19>=$M$9,P19<=$N$9),VLOOKUP(BYT,'Předpis po mesici'!$A$3:$JQ$102,P19+196,FALSE),0) -> 0 | AG19: =IF(AND(P19>=$M$9,P19<=$N$9),VLOOKUP(BYT,'Předpis po mesici'!$A$3:$JQ$102,P19+209,FALSE),0) -> 0 | AH19: =IF(AND(P19>=$M$9,P19<=$N$9),VLOOKUP(BYT,'Předpis po mesici'!$A$3:$JQ$102,P19+222,FALSE),0) -> 0 | AI19: =IF(AND(P19>=$M$9,P19<=$N$9),VLOOKUP(BYT,'Předpis po mesici'!$A$3:$JQ$102,P19+157,FALSE),0) -> 0 | AJ19: =IF(AND(P19>=$M$9,P19<=$N$9),VLOOKUP(BYT,'Počet osob'!$A$2:$JR$102,P19+2,FALSE),0) -> 4 | AK19: =IF(AND(P19>=$M$9,P19<=$N$9),VLOOKUP(BYT,'Předpis po mesici'!$A$3:$JQ$102,P19+144,FALSE),0) -> 0 | AL19: =IF(AND(P19>=$M$9,P19<=$N$9),VLOOKUP(BYT,'Předpis po mesici'!$A$3:$JQ$102,P19+248,FALSE),0) -> 0 | AM19: =IF(AND(P19>=$M$9,P19<=$N$9),VLOOKUP(BYT,'Předpis po mesici'!$A$3:$JQ$102,P19+235,FALSE),0) -> 0 | AN19: =IF(AND(P19>=$M$9,P19<=$N$9),VLOOKUP(BYT,'Předpis po mesici'!$A$3:$JQ$102,P19+235,FALSE),0) -> 0
