Workbook
Name BYT: 'vstupní data'!$B$4
Name BYT: 'vstupní data'!$B$4
Name BYTOVE_DOMY: 'Bytové domy'!$A$1
Name DŮM: 'vstupní data'!$B$3
Name DŮM: 'vstupní data'!$B$3
Name dum_adresa: 'vstupní data'!$D$3
Name EVIDENCE: 'Evidence'!$A$1
Name FAKTURY_ZA_SLUZBY: 'faktury za služby'!$A$1
Name NAKLADY_BYTOVY_DUM_ZA_ROK: 'Rozpočet domu'!$A$1
Name NAKLADY_BYTOVY_DUM_ZA_ROK: 'Náklady na dům'!$A$1
Name POCET_OSOB: 'Počet osob'!$A$1
Name PREDPISI_PO_MESICI: 'Předpis po mesici'!$B$1
Name PREPLATKY_NEDOPLATKY: 'Přeplatky nedoplatky'!$A$1
Name PRIJEM_SVJ_BEZ_VYDAJU: 'prijem SVJ bez vydaju'!$A$1
Name PRIJEM_SVJ_VCETNE_VYDAJU: 'prijem SVJ'!$A$1
Name Print_Area_Ucto: 'Vyúčtování byt - 1.část'!$A$1:$L$63
Name Print_Area_Ucto: 'Zálohy byt - měsíčně'!$A$1:$Q$35
Name TEPLO: 'Teplo'!$A$1
Name UHRADY: 'uhrady'!$A$1
Name VB_Jednotka_Osvětlení: 'Vyúčtování byt - 1.část'!$C$10
Name VB_Jednotka_Osvětlení: 'Zálohy byt - měsíčně'!$C$10
Name VB_PDF_name: 'Vyúčtování byt - 1.část'!$P$38
Name VB_preplatky_celkem: 'Vyúčtování byt - 1.část'!$K$34
Name VB_preplatky_celkem: 'Zálohy byt - měsíčně'!$P$33
Name VD_celková_plocha_jednotky: 'vstupní data'!$B$25
Name VD_celková_plocha_jednotky: 'vstupní data'!$B$25
Name VD_Cena_BVak: 'vstupní data'!$B$13
Name VD_Cena_BVak: 'vstupní data'!$B$13
Name VD_číslo_účtu_SVJ: 'vstupní data'!$B$22
Name VD_číslo_účtu_SVJ: 'vstupní data'!$B$22
Name VD_externí_výpočet_nákladů_tepla: 'vstupní data'!$B$29
Name VD_externí_výpočet_nákladů_tepla: 'vstupní data'!$B$29
Name vd_faktury_za_sluzby: 'faktury za služby'!$1:$9
Name VD_jméno: 'vstupní data'!$B$5
Name VD_jméno: 'vstupní data'!$B$5
Name VD_odečet_SV_vody_za_daný_rok: 'vstupní data'!$B$23
Name VD_odečet_SV_vody_za_daný_rok: 'vstupní data'!$B$23
Name VD_odečet_TUV_za_daný_rok: 'vstupní data'!$B$24
Name VD_odečet_TUV_za_daný_rok: 'vstupní data'!$B$24
Name VD_Počet_jednotek: 'vstupní data'!$B$17
Name VD_Počet_jednotek: 'vstupní data'!$B$17
Name VD_Počet_komínů: 'vstupní data'!$B$20
Name VD_počet_měsíců_úžívání: 'vstupní data'!$B$15
Name VD_počet_měsíců_úžívání: 'vstupní data'!$B$15
Name VD_Počet_osob: 'vstupní data'!$B$21
Name VD_přeplatek_aktuální_rok: 'vstupní data'!$B$11
Name VD_přeplatek_z_minula: 'vstupní data'!$B$10
Name VD_reklamace_do: 'vstupní data'!$B$14
Name VD_spoluvlastnictví_podíl: 'vstupní data'!$B$27
Name VD_účet_vlastníka: 'vstupní data'!$B$7
Name VD_účet_vlastníka: 'vstupní data'!$B$7
Name VD_účetní_období: 'vstupní data'!$B$8
Name VD_Užitná_plocha_domu_celkem: 'vstupní data'!$B$18
Name VD_Užitná_plocha_domu_započitatelná: 'vstupní data'!$B$19
Name VD_VS: 'vstupní data'!$B$6
Name VD_VS: 'vstupní data'!$B$6
Name VD_vyplaceno_do: 'vstupní data'!$B$16
Name VD_výpočet_vlastnického_podílu: 'vstupní data'!$B$28
Name VD_výpočet_vlastnického_podílu: 'vstupní data'!$B$28
Name VD_výsledek_vyúčtování: 'vstupní data'!$B$9

Sheet Zborovská 2 - s vodoměry
A1: =#REF! -> 0
A3: =#REF! -> 0
A4: =#REF! -> 0 | C4: =#REF! -> 0 | F4: =#REF! -> 0 | H4: =#REF! -> 0 | J4: =#REF! -> 0 | K4: =#REF! -> 0
A5: =#REF! -> 0 | C5: =#REF! -> 0 | F5: =#REF! -> 0 | H5: =#REF! -> 0 | J5: =#REF! -> 0 | K5: =#REF! -> 0
A7: =#REF! -> 0
E9: =#REF! -> 0 | H9: =#REF! -> 0
A10: =#REF! -> 0 | C10: =#REF! -> 0 | D10: =#REF! -> 0 | E10: =#REF! -> 0 | F10: =#REF! -> 0 | G10: =#REF! -> 0 | H10: =#REF! -> 0 | I10: =#REF! -> 0 | J10: =#REF! -> 0 | K10: =#REF! -> 0
A11: =#REF! -> 0 | C11: =#REF! -> 0 | D11: =#REF! -> 0 | E11: =#REF! -> 0 | F11: =#REF! -> 0 | G11: =ROUND(E11/F11,2) -> 0 | H11: =#REF! -> 0 | I11: =#REF! -> 0 | J11: =#REF! -> 0 | K11: =J11-I11 -> 0
A12: =#REF! -> 0 | C12: =#REF! -> 0 | D12: =#REF! -> 0 | E12: =#REF! -> 0 | F12: =#REF! -> 0 | G12: =ROUND(E12/F12,2) -> 0 | H12: =#REF! -> 0 | I12: =#REF! -> 0 | J12: =#REF! -> 0 | K12: =J12-I12 -> 0
A13: =#REF! -> 0 | C13: =#REF! -> 0 | D13: =#REF! -> 0 | E13: =#REF! -> 0 | F13: =#REF! -> 0 | G13: =ROUND(E13/F13,2) -> 0 | H13: =#REF! -> 0 | I13: =#REF! -> 0 | J13: =#REF! -> 0 | K13: =J13-I13 -> 0
A14: =#REF! -> 0 | C14: =#REF! -> 0 | D14: =#REF! -> 0 | E14: =#REF! -> 0 | F14: ='Počet osob'!P104 -> 0 | G14: =ROUND(E14/F14,2) -> 0 | H14: =LOOKUP('vstupní data'!B4,'Počet osob'!A:A,'Počet osob'!P:P) -> 0 | I14: =H14*G14 -> 0 | J14: =#REF! -> 0 | K14: =J14-I14 -> 0
A15: =#REF! -> 0 | C15: =#REF! -> 0 | D15: =#REF! -> 0 | E15: =#REF! -> 0 | F15: =#REF! -> 0 | G15: =#REF! -> 0 | H15: =#REF! -> 0 | I15: =#REF! -> 0 | J15: =#REF! -> 0 | K15: =#REF! -> 0
A16: =#REF! -> 0 | C16: =#REF! -> 0 | D16: =#REF! -> 0 | E16: =#REF! -> 0 | F16: =#REF! -> 0 | G16: =#REF! -> 0 | H16: =#REF! -> 0 | I16: =#REF! -> 0 | J16: =#REF! -> 0 | K16: =#REF! -> 0
A17: =#REF! -> 0 | C17: =#REF! -> 0 | D17: =#REF! -> 0 | E17: =#REF! -> 0 | F17: =#REF! -> 0 | G17: =#REF! -> 0 | H17: =#REF! -> 0 | I17: =#REF! -> 0 | J17: =#REF! -> 0 | K17: =#REF! -> 0
A18: =#REF! -> 0 | C18: =#REF! -> 0 | D18: =#REF! -> 0 | E18: ='faktury za služby'!J43 -> 0 | F18: =#REF! -> 0 | G18: =ROUND(E18/F18,2) -> 0 | H18: =#REF! -> 0 | I18: =#REF! -> 0 | J18: =#REF! -> 0 | K18: =J18-I18 -> 0
A19: =#REF! -> 0 | C19: =#REF! -> 0 | D19: =#REF! -> 0 | E19: =#REF! -> 0 | F19: =#REF! -> 0 | G19: =#REF! -> 0 | H19: =#REF! -> 0 | I19: =#REF! -> 0 | J19: =#REF! -> 0 | K19: =#REF! -> 0
C20: =#REF! -> 0 | D20: =#REF! -> 0 | E20: =#REF! -> 0 | F20: =#REF! -> 0 | G20: =#REF! -> 0 | H20: =#REF! -> 0 | I20: =#REF! -> 0
A21: =#REF! -> 0 | C21: =#REF! -> 0 | D21: =#REF! -> 0 | E21: =#REF! -> 0 | F21: =#REF! -> 0 | G21: =ROUND(E21/F21,2) -> 0 | H21: =#REF! -> 0 | I21: =#REF! -> 0 | J21: =#REF! -> 0 | K21: =J21-I21 -> 0
A22: =#REF! -> 0 | C22: =#REF! -> 0 | D22: =#REF! -> 0 | E22: =#REF! -> 0 | F22: =#REF! -> 0 | G22: =#REF! -> 0 | H22: =#REF! -> 0 | I22: =#REF! -> 0 | J22: =#REF! -> 0 | K22: =#REF! -> 0
A23: =#REF! -> 0 | E23: =SUM(E11:E21) -> 0 | G23: =#REF! -> 0 | I23: =SUM(I11:I21) -> 0 | J23: =SUM(J11:J21) -> 0 | K23: =SUM(K11:K21) -> 0
G24: =#REF! -> 0 | K24: =#REF! -> 0
G25: =#REF! -> 0 | K25: =K24+K23 -> 0
E26: =#REF! -> 0
A28: =#REF! -> 0
A29: =#REF! -> 0 | B29: =#REF! -> 0 | C29: =#REF! -> 0 | D29: =#REF! -> 0 | E29: =#REF! -> 0 | F29: =#REF! -> 0 | G29: =#REF! -> 0 | H29: =#REF! -> 0 | ... L29: =#REF! -> 0
A30: =#REF! -> 0 | B30: =#REF! -> 0 | C30: =#REF! -> 0 | D30: =#REF! -> 0 | E30: =#REF! -> 0 | F30: =#REF! -> 0 | G30: =#REF! -> 0 | H30: =#REF! -> 0 | ... L30: =#REF! -> 0
A31: =#REF! -> 0
A32: =#REF! -> 0 | B32: =#REF! -> 0 | C32: =#REF! -> 0 | D32: =#REF! -> 0 | E32: =#REF! -> 0 | F32: =#REF! -> 0 | G32: =#REF! -> 0 | H32: =#REF! -> 0 | ... L32: =#REF! -> 0
A33: =#REF! -> 0 | B33: =#REF! -> 0 | C33: =#REF! -> 0 | D33: =#REF! -> 0 | E33: =#REF! -> 0 | F33: =#REF! -> 0 | G33: =#REF! -> 0 | H33: =#REF! -> 0 | ... L33: =#REF! -> 0
A34: =#REF! -> 0 | C34: =#REF! -> 0
A36: =#REF! -> 0
A37: =#REF! -> 0 | C37: =#REF! -> 0 | E37: =#REF! -> 0 | G37: =#REF! -> 0 | I37: =#REF! -> 0 | K37: =#REF! -> 0
A38: =#REF! -> 0 | C38: =#REF! -> 0 | E38: =#REF! -> 0 | G38: =#REF! -> 0 | I38: =#REF! -> 0 | K38: =#REF! -> 0
A39: =#REF! -> 0 | C39: =#REF! -> 0 | E39: =#REF! -> 0 | G39: =#REF! -> 0 | I39: =#REF! -> 0 | K39: =#REF! -> 0
A41: =#REF! -> 0
A42: =#REF! -> 0
A43: =#REF! -> 0
A44: =#REF! -> 0

Sheet Zborovská 2 - bez vodoměrů
A1: =#REF! -> 0
A3: =#REF! -> 0
A4: =#REF! -> 0 | C4: =#REF! -> 0 | F4: =#REF! -> 0 | H4: =#REF! -> 0 | J4: =#REF! -> 0 | K4: =#REF! -> 0
A5: =#REF! -> 0 | C5: =#REF! -> 0 | F5: =#REF! -> 0 | H5: =#REF! -> 0 | J5: =#REF! -> 0 | K5: =#REF! -> 0
A7: =#REF! -> 0
E9: =#REF! -> 0 | H9: =#REF! -> 0
A10: =#REF! -> 0 | C10: =#REF! -> 0 | D10: =#REF! -> 0 | E10: =#REF! -> 0 | F10: =#REF! -> 0 | G10: =#REF! -> 0 | H10: =#REF! -> 0 | I10: =#REF! -> 0 | J10: =#REF! -> 0 | K10: =#REF! -> 0
A11: =#REF! -> 0 | C11: =#REF! -> 0 | D11: =#REF! -> 0 | E11: =#REF! -> 0 | F11: =#REF! -> 0 | G11: =ROUND(E11/F11,2) -> 0 | H11: =#REF! -> 0 | I11: =G11*H11 -> 0 | J11: =#REF! -> 0 | K11: =#REF! -> 0
A12: =#REF! -> 0 | C12: =#REF! -> 0 | D12: =#REF! -> 0 | E12: =#REF! -> 0 | F12: =#REF! -> 0 | G12: =ROUND(E12/F12,2) -> 0 | H12: =#REF! -> 0 | I12: =G12*H12 -> 0 | J12: =#REF! -> 0 | K12: =#REF! -> 0
A13: =#REF! -> 0 | C13: =#REF! -> 0 | D13: =#REF! -> 0 | E13: =#REF! -> 0 | F13: =#REF! -> 0 | G13: =ROUND(E13/F13,2) -> 0 | H13: =#REF! -> 0 | I13: =G13*H13 -> 0 | J13: =#REF! -> 0 | K13: =#REF! -> 0
A14: =#REF! -> 0 | C14: =#REF! -> 0 | D14: =#REF! -> 0 | E14: =#REF! -> 0 | F14: ='Počet osob'!P104 -> 0 | G14: =ROUND(E14/F14,2) -> 0 | H14: =LOOKUP('vstupní data'!B4,'Počet osob'!A:A,'Počet osob'!P:P) -> 0 | I14: =G14*H14 -> 0 | J14: =#REF! -> 0 | K14: =J14-I14 -> 0
A15: =#REF! -> 0 | C15: =#REF! -> 0 | D15: =#REF! -> 0 | E15: =#REF! -> 0 | F15: =#REF! -> 0 | G15: =#REF! -> 0 | H15: =#REF! -> 0 | I15: =#REF! -> 0 | J15: =#REF! -> 0 | K15: =#REF! -> 0
A16: =#REF! -> 0 | C16: =#REF! -> 0 | D16: =#REF! -> 0 | E16: =#REF! -> 0 | F16: =#REF! -> 0 | G16: =#REF! -> 0 | H16: =#REF! -> 0 | I16: =#REF! -> 0 | J16: =#REF! -> 0 | K16: =#REF! -> 0
A17: =#REF! -> 0 | C17: =#REF! -> 0 | D17: =#REF! -> 0 | E17: =#REF! -> 0 | F17: =#REF! -> 0 | G17: =#REF! -> 0 | H17: =#REF! -> 0 | I17: =#REF! -> 0 | J17: =#REF! -> 0 | K17: =#REF! -> 0
A18: =#REF! -> 0 | C18: =#REF! -> 0 | D18: =#REF! -> 0 | E18: ='faktury za služby'!J42 -> 0 | F18: ='Počet osob'!Q104 -> 0 | G18: =ROUND(E18/F18,2) -> 0 | H18: =#REF! -> 0 | I18: =G18*H18 -> 0 | J18: =#REF! -> 0 | K18: =#REF! -> 0
A19: =#REF! -> 0 | C19: =#REF! -> 0 | D19: =#REF! -> 0 | E19: =#REF! -> 0 | F19: =#REF! -> 0 | G19: =#REF! -> 0 | H19: =#REF! -> 0 | I19: =#REF! -> 0 | J19: =#REF! -> 0 | K19: =#REF! -> 0
C20: =#REF! -> 0 | D20: =#REF! -> 0 | E20: =#REF! -> 0 | F20: =#REF! -> 0 | G20: =#REF! -> 0 | H20: =#REF! -> 0 | I20: =#REF! -> 0
A21: =#REF! -> 0 | C21: =#REF! -> 0 | D21: =#REF! -> 0 | E21: =#REF! -> 0 | F21: =#REF! -> 0 | G21: =ROUND(E21/F21,2) -> 0 | H21: =#REF! -> 0 | I21: =G21*H21 -> 0 | J21: =#REF! -> 0 | K21: =#REF! -> 0
A22: =#REF! -> 0 | C22: =#REF! -> 0 | D22: =#REF! -> 0 | E22: =#REF! -> 0 | F22: =#REF! -> 0 | G22: =#REF! -> 0 | H22: =#REF! -> 0 | I22: =#REF! -> 0 | J22: =#REF! -> 0 | K22: =#REF! -> 0
A23: =#REF! -> 0 | E23: =SUM(E11:E21) -> 0 | G23: =#REF! -> 0 | I23: =SUM(I11:I21) -> 0 | J23: =SUM(J11:J21) -> 0 | K23: =SUM(K11:K21) -> 0
G24: =#REF! -> 0 | K24: =#REF! -> 0
G25: =#REF! -> 0 | K25: =K23+K24 -> 0
E26: =#REF! -> 0
A28: =#REF! -> 0
A29: =#REF! -> 0 | B29: =#REF! -> 0 | C29: =#REF! -> 0 | D29: =#REF! -> 0 | E29: =#REF! -> 0 | F29: =#REF! -> 0 | G29: =#REF! -> 0 | H29: =#REF! -> 0 | ... L29: =#REF! -> 0
A30: =#REF! -> 0 | B30: =#REF! -> 0 | C30: =#REF! -> 0 | D30: =#REF! -> 0 | E30: =#REF! -> 0 | F30: =#REF! -> 0 | G30: =#REF! -> 0 | H30: =#REF! -> 0 | ... L30: =#REF! -> 0
A31: =#REF! -> 0
A32: =#REF! -> 0 | B32: =#REF! -> 0 | C32: =#REF! -> 0 | D32: =#REF! -> 0 | E32: =#REF! -> 0 | F32: =#REF! -> 0 | G32: =#REF! -> 0 | H32: =#REF! -> 0 | ... L32: =#REF! -> 0
A33: =#REF! -> 0 | B33: =#REF! -> 0 | C33: =#REF! -> 0 | D33: =#REF! -> 0 | E33: =#REF! -> 0 | F33: =#REF! -> 0 | G33: =#REF! -> 0 | H33: =#REF! -> 0 | ... L33: =#REF! -> 0
A34: =#REF! -> 0 | C34: =#REF! -> 0
A36: =#REF! -> 0
A37: =#REF! -> 0 | C37: =#REF! -> 0 | E37: =#REF! -> 0 | G37: =#REF! -> 0 | I37: =#REF! -> 0 | K37: =#REF! -> 0
A38: =#REF! -> 0 | C38: =#REF! -> 0 | E38: =#REF! -> 0 | G38: =#REF! -> 0 | I38: =#REF! -> 0 | K38: =#REF! -> 0
A39: =#REF! -> 0 | C39: =#REF! -> 0 | E39: =#REF! -> 0 | G39: =#REF! -> 0 | I39: =#REF! -> 0 | K39: =#REF! -> 0
A41: =#REF! -> 0
A42: =#REF! -> 0
A43: =#REF! -> 0
A44: =#REF! -> 0

Sheet export send mail
A1: SEZNAM | B1: Email | C1: Celé jméno | D1: Stav | E1: Mobil | F1: Jméno | G1: Příjmení | H1: ID | I1: Adresa | J1: Bytový dům | K1: Jednotka číslo | L1: Soubor na poslání | M1: Datum narození | N1: Oslovení | O1: Příloha 2
B2: =Evidence!D2 -> 0 | C2: =Evidence!B2 -> 0 | E2: =Evidence!E2 -> 0 | I2: =Evidence!C2 -> 0 | J2: =dum_adresa -> 0 | K2: =Evidence!A2 -> 0 | L2: =("C:\sprava\"&SUBSTITUTE(K2,"/","")&".pdf") -> 0
B3: =Evidence!D3 -> 0 | C3: =Evidence!B3 -> 0 | E3: =Evidence!E3 -> 0 | I3: =Evidence!C3 -> 0 | J3: =dum_adresa -> 0 | K3: =Evidence!A3 -> 0 | L3: =("C:\sprava\"&SUBSTITUTE(K3,"/","")&".pdf") -> 0 | N3: Vážený pane inženýre,
B4: =Evidence!D4 -> 0 | C4: =Evidence!B4 -> 0 | E4: =Evidence!E4 -> 0 | I4: =Evidence!C4 -> 0 | J4: =dum_adresa -> 0 | K4: =Evidence!A4 -> 0 | L4: =("C:\sprava\"&SUBSTITUTE(K4,"/","")&".pdf") -> 0 | N4: Vážená paní Pařízková,
B5: =Evidence!D5 -> 0 | C5: =Evidence!B5 -> 0 | E5: =Evidence!E5 -> 0 | I5: =Evidence!C5 -> 0 | J5: =dum_adresa -> 0 | K5: =Evidence!A5 -> 0 | L5: =("C:\sprava\"&SUBSTITUTE(K5,"/","")&".pdf") -> 0 | N5: Vážená paní inženýrko,
B6: =Evidence!D6 -> 0 | C6: =Evidence!B6 -> 0 | E6: =Evidence!E6 -> 0 | I6: =Evidence!C6 -> 0 | J6: =dum_adresa -> 0 | K6: =Evidence!A6 -> 0 | L6: =("C:\sprava\"&SUBSTITUTE(K6,"/","")&".pdf") -> 0 | N6: Vážený pane Pelko,
B7: =Evidence!D7 -> 0 | C7: =Evidence!B7 -> 0 | E7: =Evidence!E7 -> 0 | I7: =Evidence!C7 -> 0 | J7: =dum_adresa -> 0 | K7: =Evidence!A7 -> 0 | L7: =("C:\sprava\"&SUBSTITUTE(K7,"/","")&".pdf") -> 0 | N7: Vážená paní Šťastná,
B8: =Evidence!D8 -> 0 | C8: =Evidence!B8 -> 0 | E8: =Evidence!E8 -> 0 | I8: =Evidence!C8 -> 0 | J8: =dum_adresa -> 0 | K8: =Evidence!A8 -> 0 | L8: =("C:\sprava\"&SUBSTITUTE(K8,"/","")&".pdf") -> 0 | N8: Vážený pane magistře,
B9: =Evidence!D9 -> 0 | C9: =Evidence!B9 -> 0 | E9: =Evidence!E9 -> 0 | I9: =Evidence!C9 -> 0 | J9: =dum_adresa -> 0 | K9: =Evidence!A9 -> 0 | L9: =("C:\sprava\"&SUBSTITUTE(K9,"/","")&".pdf") -> 0 | N9: Vážená paní inženýrko,
B10: =Evidence!D10 -> 0 | C10: =Evidence!B10 -> 0 | E10: =Evidence!E10 -> 0 | I10: =Evidence!C10 -> 0 | J10: =dum_adresa -> 0 | K10: =Evidence!A10 -> 0 | L10: =("C:\sprava\"&SUBSTITUTE(K10,"/","")&".pdf") -> 0 | N10: Vážený pane magistře,
B11: =Evidence!D11 -> 0 | C11: =Evidence!B11 -> 0 | E11: =Evidence!E11 -> 0 | I11: =Evidence!C11 -> 0 | J11: =dum_adresa -> 0 | K11: =Evidence!A11 -> 0 | L11: =("C:\sprava\"&SUBSTITUTE(K11,"/","")&".pdf") -> 0 | N11: Vážený pane inženýre,
B12: =Evidence!D12 -> 0 | C12: =Evidence!B12 -> 0 | E12: =Evidence!E12 -> 0 | I12: =Evidence!C12 -> 0 | J12: =dum_adresa -> 0 | K12: =Evidence!A12 -> 0 | L12: =("C:\sprava\"&SUBSTITUTE(K12,"/","")&".pdf") -> 0 | N12: Vážená paní doktorko,
B13: =Evidence!D13 -> 0 | C13: =Evidence!B13 -> 0 | E13: =Evidence!E13 -> 0 | I13: =Evidence!C13 -> 0 | J13: =dum_adresa -> 0 | K13: =Evidence!A13 -> 0 | L13: =("C:\sprava\"&SUBSTITUTE(K13,"/","")&".pdf") -> 0 | N13: Vážený pane inženýre,
B14: =Evidence!D14 -> 0 | C14: =Evidence!B14 -> 0 | E14: =Evidence!E14 -> 0 | I14: =Evidence!C14 -> 0 | J14: =dum_adresa -> 0 | K14: =Evidence!A14 -> 0 | L14: =("C:\sprava\"&SUBSTITUTE(K14,"/","")&".pdf") -> 0 | N14: Vážená paní doktorko,
... B59: =Evidence!D59 -> 0 | C59: =Evidence!B59 -> 0 | E59: =Evidence!E59 -> 0 | I59: =Evidence!C59 -> 0 | J59: =dum_adresa -> 0 | K59: =Evidence!A59 -> 0 | L59: =("C:\sprava\"&SUBSTITUTE(K59,"/","")&".pdf") -> 0 | N59: Vážený pane inženýre,
B60: =Evidence!D60 -> 0 | C60: =Evidence!B60 -> 0 | E60: =Evidence!E60 -> 0 | I60: =Evidence!C60 -> 0 | J60: =dum_adresa -> 0 | K60: =Evidence!A60 -> 0 | L60: =("C:\sprava\"&SUBSTITUTE(K60,"/","")&".pdf") -> 0
B61: =Evidence!D61 -> 0 | C61: =Evidence!B61 -> 0 | E61: =Evidence!E61 -> 0 | I61: =Evidence!C61 -> 0 | J61: =dum_adresa -> 0 | K61: =Evidence!A61 -> 0 | L61: =("C:\sprava\"&SUBSTITUTE(K61,"/","")&".pdf") -> 0
B62: =Evidence!D62 -> 0 | C62: =Evidence!B62 -> 0 | E62: =Evidence!E62 -> 0 | I62: =Evidence!C62 -> 0 | J62: =dum_adresa -> 0 | K62: =Evidence!A62 -> 0 | L62: =("C:\sprava\"&SUBSTITUTE(K62,"/","")&".pdf") -> 0
B63: =Evidence!D63 -> 0 | C63: =Evidence!B63 -> 0 | E63: =Evidence!E63 -> 0 | I63: =Evidence!C63 -> 0 | J63: =dum_adresa -> 0 | K63: =Evidence!A63 -> 0 | L63: =("C:\sprava\"&SUBSTITUTE(K63,"/","")&".pdf") -> 0
B64: =Evidence!D64 -> 0 | C64: =Evidence!B64 -> 0 | E64: =Evidence!E64 -> 0 | I64: =Evidence!C64 -> 0 | J64: =dum_adresa -> 0 | K64: =Evidence!A64 -> 0 | L64: =("C:\sprava\"&SUBSTITUTE(K64,"/","")&".pdf") -> 0
B65: =Evidence!D65 -> 0 | C65: =Evidence!B65 -> 0 | E65: =Evidence!E65 -> 0 | I65: =Evidence!C65 -> 0 | J65: =dum_adresa -> 0 | K65: =Evidence!A65 -> 0 | L65: =("C:\sprava\"&SUBSTITUTE(K65,"/","")&".pdf") -> 0
B66: =Evidence!D66 -> 0 | C66: =Evidence!B66 -> 0 | E66: =Evidence!E66 -> 0 | I66: =Evidence!C66 -> 0 | J66: =dum_adresa -> 0 | K66: =Evidence!A66 -> 0 | L66: =("C:\sprava\"&SUBSTITUTE(K66,"/","")&".pdf") -> 0
B67: =Evidence!D67 -> 0 | C67: =Evidence!B67 -> 0 | E67: =Evidence!E67 -> 0 | I67: =Evidence!C67 -> 0 | J67: =dum_adresa -> 0 | K67: =Evidence!A67 -> 0 | L67: =("C:\sprava\"&SUBSTITUTE(K67,"/","")&".pdf") -> 0
B68: =Evidence!D68 -> 0 | C68: =Evidence!B68 -> 0 | E68: =Evidence!E68 -> 0 | I68: =Evidence!C68 -> 0 | J68: =dum_adresa -> 0 | K68: =Evidence!A68 -> 0 | L68: =("C:\sprava\"&SUBSTITUTE(K68,"/","")&".pdf") -> 0
B69: =Evidence!D69 -> 0 | C69: =Evidence!B69 -> 0 | E69: =Evidence!E69 -> 0 | I69: =Evidence!C69 -> 0 | J69: =dum_adresa -> 0 | K69: =Evidence!A69 -> 0 | L69: =("C:\sprava\"&SUBSTITUTE(K69,"/","")&".pdf") -> 0
B70: =Evidence!D70 -> 0 | C70: =Evidence!B70 -> 0 | E70: =Evidence!E70 -> 0 | I70: =Evidence!C70 -> 0 | J70: =dum_adresa -> 0 | K70: =Evidence!A70 -> 0 | L70: =("C:\sprava\"&SUBSTITUTE(K70,"/","")&".pdf") -> 0
B71: =Evidence!D71 -> 0 | C71: =Evidence!B71 -> 0 | E71: =Evidence!E71 -> 0 | I71: =Evidence!C71 -> 0 | J71: =dum_adresa -> 0 | K71: =Evidence!A71 -> 0 | L71: =("C:\sprava\"&SUBSTITUTE(K71,"/","")&".pdf") -> 0
... B232: =Evidence!D232 -> 0 | C232: =Evidence!B232 -> 0 | E232: =Evidence!E232 -> 0 | I232: =Evidence!C232 -> 0 | J232: =dum_adresa -> 0 | K232: =Evidence!A232 -> 0 | L232: =("C:\sprava\"&SUBSTITUTE(K232,"/","")&".pdf") -> 0

Sheet Zálohy byt - měsíčně
A1: AdminReal s.r.o., Veveří 2581/102 , 616 00 Brno, IČO 02827476, Zapsáno KS v Brně, oddíl C, vložka 82606
A2: ='vstupní data'!B5 -> 0
A3: adresa společenství: | C3: =dum_adresa -> 0 | F3: bankovní spojení člena: | H3: ='vstupní data'!B7 -> 0 | K3: č. prostoru: | P3: ='vstupní data'!B4 -> 0
A4: bankovní spojení společenství: | C4: ='vstupní data'!B22 -> 0 | E4: variabilní symbol pro platbu nedoplatku: | H4: ='vstupní data'!B6 -> 0 | K4: zůčtovací období: | P4: =IF('vstupní data'!D15="první část roku",'vstupní data'!E17,'vstupní data'!H17) -> 0
A6: MENU | O6: POČET OSOB | P6: =IF(P7 > 0, "Navýšení předpisu o částku", "Snížení předpisu o částku") -> 0 | Q6: Navýšení předpis o částku (ručně)
O7: ='vstupní data'!AJ30 -> 0 | P7: =IF(Q7=0, IF(A38>0, -ROUND((A38*0.95)/VD_počet_měsíců_úžívání, 0), -ROUND((A38*1.05)/VD_počet_měsíců_úžívání, 0)), Q7) -> 0 | Q7: 5 | R7: * pokud nula vypočítá si sám pokud se zadá vezme dané číslo
E8: Odběrné místo (dům) | H8: Uživatel
A9: Položka | B9: Sloupec1 | C9: Jednotka | D9: Podíl | E9: Náklad | F9: Jednotek | G9: Kč/jedn | H9: Jednotek2 | I9: Záloha (aktuální) | J9: Náklad za rok | K9: Nový náklad -+% | L9: Přeplatky | nedoplatky | M9: Záloha měsíčně (aktuální) | N9: Záloha měsíčně (nová do OS po navýšení o %) | O9: Záloha měsíčně (dle počtu osob) | P9: Záloha měsíčně (nová do OS po navýšení o částku) | Q9: Navýšení o kolik procent?
A10: =Faktury!A4 -> 0 | C10: =Faktury!C4 -> 0 | D10: =Faktury!D4 -> 0 | E10: =Faktury!E4 -> 0 | F10: =Faktury!F4 -> 0 | G10: =Faktury!G4 -> 0 | H10: =Faktury!H4 -> 0 | I10: ='Vyúčtování byt - 1.část'!J10 -> 0 | J10: =Faktury!I4 -> 0 | K10: =IF(J10=0,0,J10*(100+Q10)/100) -> 0 | L10: ='Vyúčtování byt - 1.část'!K10 -> 0 | M10: =ROUND(I10/VD_počet_měsíců_úžívání,2) -> 0 | N10: =IF(C10="počet osob", CEILING(K10/'vstupní data'!$AJ$31/VD_počet_měsíců_úžívání*($O$7*12), 10), ROUNDUP(K10/VD_počet_měsíců_úžívání, -1)) -> 0 | O10: =CEILING(K10/'vstupní data'!$AJ$31/VD_počet_měsíců_úžívání*($O$7*12),10) -> 0 | P10: =ROUND(MAX(0,I10/VD_počet_měsíců_úžívání-IF($P$7>0,L10/VD_počet_měsíců_úžívání*1.05,L10/VD_počet_měsíců_úžívání*0.95)),0) -> 0 | Q10: 0
A11: =Faktury!A5 -> 0 | C11: =Faktury!C5 -> 0 | D11: =Faktury!D5 -> 0 | E11: =Faktury!E5 -> 0 | F11: =Faktury!F5 -> 0 | G11: =Faktury!G5 -> 0 | H11: =Faktury!H5 -> 0 | I11: ='Vyúčtování byt - 1.část'!J11 -> 0 | J11: =Faktury!I5 -> 0 | K11: =IF(J11=0,0,J11*(100+Q11)/100) -> 0 | L11: ='Vyúčtování byt - 1.část'!K11 -> 0 | M11: =ROUND(I11/VD_počet_měsíců_úžívání,2) -> 0 | N11: =IF(C11="počet osob", CEILING(K11/'vstupní data'!$AJ$31/VD_počet_měsíců_úžívání*($O$7*12), 10), ROUNDUP(K11/VD_počet_měsíců_úžívání, -1)) -> 0 | O11: =CEILING(K11/'vstupní data'!$AJ$31/VD_počet_měsíců_úžívání*($O$7*12),10) -> 0 | P11: =ROUND(MAX(0,I11/VD_počet_měsíců_úžívání-IF($P$7>0,L11/VD_počet_měsíců_úžívání*1.05,L11/VD_počet_měsíců_úžívání*0.95)),0) -> 0 | Q11: 0
A12: =Faktury!A6 -> 0 | C12: =Faktury!C6 -> 0 | D12: =Faktury!D6 -> 0 | E12: =Faktury!E6 -> 0 | F12: =Faktury!F6 -> 0 | G12: =Faktury!G6 -> 0 | H12: =Faktury!H6 -> 0 | I12: ='Vyúčtování byt - 1.část'!J12 -> 0 | J12: =Faktury!I6 -> 0 | K12: =IF(J12=0,0,J12*(100+Q12)/100) -> 0 | L12: ='Vyúčtování byt - 1.část'!K12 -> 0 | M12: =ROUND(I12/VD_počet_měsíců_úžívání,2) -> 0 | N12: =IF(C12="počet osob", CEILING(K12/'vstupní data'!$AJ$31/VD_počet_měsíců_úžívání*($O$7*12), 10), ROUNDUP(K12/VD_počet_měsíců_úžívání, -1)) -> 0 | O12: =CEILING(K12/'vstupní data'!$AJ$31/VD_počet_měsíců_úžívání*($O$7*12),10) -> 0 | P12: =ROUND(MAX(0,I12/VD_počet_měsíců_úžívání-IF($P$7>0,L12/VD_počet_měsíců_úžívání*1.05,L12/VD_počet_měsíců_úžívání*0.95)),0) -> 0 | Q12: 0
A13: =Faktury!A7 -> 0 | C13: =Faktury!C7 -> 0 | D13: =Faktury!D7 -> 0 | E13: =Faktury!E7 -> 0 | F13: =Faktury!F7 -> 0 | G13: =Faktury!G7 -> 0 | H13: =Faktury!H7 -> 0 | I13: ='Vyúčtování byt - 1.část'!J13 -> 0 | J13: =Faktury!I7 -> 0 | K13: =IF(J13=0,0,J13*(100+Q13)/100) -> 0 | L13: ='Vyúčtování byt - 1.část'!K13 -> 0 | M13: =ROUND(I13/VD_počet_měsíců_úžívání,2) -> 0 | N13: =IF(C13="počet osob", CEILING(K13/'vstupní data'!$AJ$31/VD_počet_měsíců_úžívání*($O$7*12), 10), ROUNDUP(K13/VD_počet_měsíců_úžívání, -1)) -> 0 | O13: =CEILING(K13/'vstupní data'!$AJ$31/VD_počet_měsíců_úžívání*($O$7*12),10) -> 0 | P13: =ROUND(MAX(0,I13/VD_počet_měsíců_úžívání-IF($P$7>0,L13/VD_počet_měsíců_úžívání*1.05,L13/VD_počet_měsíců_úžívání*0.95)),0) -> 0 | Q13: 0
A14: =Faktury!A17 -> 0 | C14: =Faktury!C17 -> 0 | D14: =Faktury!D17 -> 0 | E14: =Faktury!E17 -> 0 | F14: =Faktury!F17 -> 0 | G14: =Faktury!G17 -> 0 | H14: =Faktury!H17 -> 0 | I14: ='Vyúčtování byt - 1.část'!J14 -> 0 | J14: =Faktury!I17 -> 0 | K14: =IF(J14=0,0,J14*(100+Q14)/100) -> 0 | L14: ='Vyúčtování byt - 1.část'!K14 -> 0 | M14: =ROUND(I14/VD_počet_měsíců_úžívání,2) -> 0 | N14: =IF(C14="počet osob", CEILING(K14/'vstupní data'!$AJ$31/VD_počet_měsíců_úžívání*($O$7*12), 10), ROUNDUP(K14/VD_počet_měsíců_úžívání, -1)) -> 0 | O14: =CEILING(K14/'vstupní data'!$AJ$31/VD_počet_měsíců_úžívání*($O$7*12),10) -> 0 | P14: =ROUND(MAX(0,I14/VD_počet_měsíců_úžívání-IF($P$7>0,L14/VD_počet_měsíců_úžívání*1.05,L14/VD_počet_měsíců_úžívání*0.95)),0) -> 0 | Q14: 0
A15: =Faktury!A12 -> 0 | C15: =Faktury!C12 -> 0 | D15: =Faktury!D12 -> 0 | E15: =Faktury!E12 -> 0 | F15: =Faktury!F12 -> 0 | G15: =Faktury!G12 -> 0 | H15: =Faktury!H12 -> 0 | I15: ='Vyúčtování byt - 1.část'!J15 -> 0 | J15: =Faktury!I12 -> 0 | K15: =IF(J15=0,0,J15*(100+Q15)/100) -> 0 | L15: ='Vyúčtování byt - 1.část'!K15 -> 0 | M15: =ROUND(I15/VD_počet_měsíců_úžívání,2) -> 0 | N15: =IF(C15="počet osob", CEILING(K15/'vstupní data'!$AJ$31/VD_počet_měsíců_úžívání*($O$7*12), 10), ROUNDUP(K15/VD_počet_měsíců_úžívání, -1)) -> 0 | O15: =CEILING(K15/'vstupní data'!$AJ$31/VD_počet_měsíců_úžívání*($O$7*12),10) -> 0 | P15: =ROUND(MAX(0,I15/VD_počet_měsíců_úžívání-IF($P$7>0,L15/VD_počet_měsíců_úžívání*1.05,L15/VD_počet_měsíců_úžívání*0.95)),0) -> 0 | Q15: 0
A16: =Faktury!A9 -> 0 | C16: =Faktury!C9 -> 0 | D16: =Faktury!D9 -> 0 | E16: =Faktury!E9 -> 0 | F16: =Faktury!F9 -> 0 | G16: =Faktury!G9 -> 0 | H16: =Faktury!H9 -> 0 | I16: ='Vyúčtování byt - 1.část'!J16 -> 0 | J16: =Faktury!I9 -> 0 | K16: =IF(J16=0,0,J16*(100+Q16)/100) -> 0 | L16: ='Vyúčtování byt - 1.část'!K16 -> 0 | M16: =ROUND(I16/VD_počet_měsíců_úžívání,2) -> 0 | N16: =IF(C16="počet osob", CEILING(K16/'vstupní data'!$AJ$31/VD_počet_měsíců_úžívání*($O$7*12), 10), ROUNDUP(K16/VD_počet_měsíců_úžívání, -1)) -> 0 | O16: =CEILING(K16/'vstupní data'!$AJ$31/VD_počet_měsíců_úžívání*($O$7*12),10) -> 0 | P16: =ROUND(MAX(0,I16/VD_počet_měsíců_úžívání-IF($P$7>0,L16/VD_počet_měsíců_úžívání*1.05,L16/VD_počet_měsíců_úžívání*0.95)),0) -> 0 | Q16: 0
A17: =Faktury!A2 -> 0 | C17: =Faktury!C2 -> 0 | D17: =Faktury!D2 -> 0 | E17: =Faktury!E2 -> 0 | F17: =Faktury!F2 -> 0 | G17: =Faktury!G2 -> 0 | H17: =Faktury!H2 -> 0 | I17: ='Vyúčtování byt - 1.část'!J17 -> 0 | J17: =Faktury!I2 -> 0 | K17: =IF(J17=0,0,J17*(100+Q17)/100) -> 0 | L17: ='Vyúčtování byt - 1.část'!K17 -> 0 | M17: =ROUND(I17/VD_počet_měsíců_úžívání,2) -> 0 | N17: =IF(C17="počet osob", CEILING(K17/'vstupní data'!$AJ$31/VD_počet_měsíců_úžívání*($O$7*12), 10), ROUNDUP(K17/VD_počet_měsíců_úžívání, -1)) -> 0 | O17: =CEILING(K17/'vstupní data'!$AJ$31/VD_počet_měsíců_úžívání*($O$7*12),10) -> 0 | P17: =ROUND(MAX(0,I17/VD_počet_měsíců_úžívání-IF($P$7>0,L17/VD_počet_měsíců_úžívání*1.05,L17/VD_počet_měsíců_úžívání*0.95)),0) -> 0 | Q17: 0
A18: =Faktury!A3 -> 0 | C18: =Faktury!C3 -> 0 | D18: =Faktury!D3 -> 0 | E18: =Faktury!E3 -> 0 | F18: =Faktury!F3 -> 0 | G18: =Faktury!G3 -> 0 | H18: =Faktury!H3 -> 0 | I18: ='Vyúčtování byt - 1.část'!J18 -> 0 | J18: =Faktury!I3 -> 0 | K18: =IF(J18=0,0,J18*(100+Q18)/100) -> 0 | L18: ='Vyúčtování byt - 1.část'!K18 -> 0 | M18: =ROUND(I18/VD_počet_měsíců_úžívání,2) -> 0 | N18: =IF(C18="počet osob", CEILING(K18/'vstupní data'!$AJ$31/VD_počet_měsíců_úžívání*($O$7*12), 10), ROUNDUP(K18/VD_počet_měsíců_úžívání, -1)) -> 0 | O18: =CEILING(K18/'vstupní data'!$AJ$31/VD_počet_měsíců_úžívání*($O$7*12),10) -> 0 | P18: =ROUND(MAX(0,I18/VD_počet_měsíců_úžívání-IF($P$7>0,L18/VD_počet_měsíců_úžívání*1.05,L18/VD_počet_měsíců_úžívání*0.95)),0) -> 0 | Q18: 0
A19: =Faktury!A19 -> 0 | C19: =Faktury!C19 -> 0 | D19: =Faktury!D19 -> 0 | E19: =Faktury!E19 -> 0 | F19: =Faktury!F19 -> 0 | G19: =Faktury!G19 -> 0 | H19: =Faktury!H19 -> 0 | I19: ='Vyúčtování byt - 1.část'!J19 -> 0 | J19: =Faktury!I19 -> 0 | K19: =IF(J19=0,0,J19*(100+Q19)/100) -> 0 | L19: ='Vyúčtování byt - 1.část'!K19 -> 0 | M19: =ROUND(I19/VD_počet_měsíců_úžívání,2) -> 0 | N19: =IF(C19="počet osob", CEILING(K19/'vstupní data'!$AJ$31/VD_počet_měsíců_úžívání*($O$7*12), 10), ROUNDUP(K19/VD_počet_měsíců_úžívání, -1)) -> 0 | O19: =CEILING(K19/'vstupní data'!$AJ$31/VD_počet_měsíců_úžívání*($O$7*12),10) -> 0 | P19: =ROUND(MAX(0,I19/VD_počet_měsíců_úžívání-IF($P$7>0,L19/VD_počet_měsíců_úžívání*1.05,L19/VD_počet_měsíců_úžívání*0.95)),0) -> 0 | Q19: 0
A20: =Faktury!A18 -> 0 | C20: =Faktury!C18 -> 0 | D20: =Faktury!D18 -> 0 | E20: =Faktury!E18 -> 0 | F20: =Faktury!F18 -> 0 | G20: =Faktury!G18 -> 0 | H20: =Faktury!H18 -> 0 | I20: ='Vyúčtování byt - 1.část'!J20 -> 0 | J20: =Faktury!I18 -> 0 | K20: =IF(J20=0,0,J20*(100+Q20)/100) -> 0 | L20: ='Vyúčtování byt - 1.část'!K20 -> 0 | M20: =ROUND(I20/VD_počet_měsíců_úžívání,2) -> 0 | N20: =IF(C20="počet osob", CEILING(K20/'vstupní data'!$AJ$31/VD_počet_měsíců_úžívání*($O$7*12), 10), ROUNDUP(K20/VD_počet_měsíců_úžívání, -1)) -> 0 | O20: =CEILING(K20/'vstupní data'!$AJ$31/VD_počet_měsíců_úžívání*($O$7*12),10) -> 0 | P20: =ROUND(MAX(0,I20/VD_počet_měsíců_úžívání-IF($P$7>0,L20/VD_počet_měsíců_úžívání*1.05,L20/VD_počet_měsíců_úžívání*0.95)),0) -> 0 | Q20: 0
A21: =Faktury!A10 -> 0 | C21: =Faktury!C10 -> 0 | D21: =Faktury!D10 -> 0 | E21: =Faktury!E10 -> 0 | F21: =Faktury!F10 -> 0 | G21: =Faktury!G10 -> 0 | H21: =Faktury!H10 -> 0 | I21: ='Vyúčtování byt - 1.část'!J21 -> 0 | J21: =Faktury!I10 -> 0 | K21: =IF(J21=0,0,J21*(100+Q21)/100) -> 0 | L21: ='Vyúčtování byt - 1.část'!K21 -> 0 | M21: =ROUND(I21/VD_počet_měsíců_úžívání,2) -> 0 | N21: =IF(C21="počet osob", CEILING(K21/'vstupní data'!$AJ$31/VD_počet_měsíců_úžívání*($O$7*12), 10), ROUNDUP(K21/VD_počet_měsíců_úžívání, -1)) -> 0 | O21: =CEILING(K21/'vstupní data'!$AJ$31/VD_počet_měsíců_úžívání*($O$7*12),10) -> 0 | P21: =ROUND(MAX(0,I21/VD_počet_měsíců_úžívání-IF($P$7>0,L21/VD_počet_měsíců_úžívání*1.05,L21/VD_počet_měsíců_úžívání*0.95)),0) -> 0 | Q21: 0
A22: =Faktury!A8 -> 0 | C22: =Faktury!C8 -> 0 | D22: =Faktury!D8 -> 0 | E22: =Faktury!E8 -> 0 | F22: =Faktury!F8 -> 0 | G22: =Faktury!G8 -> 0 | H22: =Faktury!H8 -> 0 | I22: ='Vyúčtování byt - 1.část'!J22 -> 0 | J22: =Faktury!I8 -> 0 | K22: =IF(J22=0,0,J22*(100+Q22)/100) -> 0 | L22: ='Vyúčtování byt - 1.část'!K22 -> 0 | M22: =ROUND(I22/VD_počet_měsíců_úžívání,2) -> 0 | N22: =IF(C22="počet osob", CEILING(K22/'vstupní data'!$AJ$31/VD_počet_měsíců_úžívání*($O$7*12), 10), ROUNDUP(K22/VD_počet_měsíců_úžívání, -1)) -> 0 | O22: =CEILING(K22/'vstupní data'!$AJ$31/VD_počet_měsíců_úžívání*($O$7*12),10) -> 0 | P22: =ROUND(MAX(0,I22/VD_počet_měsíců_úžívání-IF($P$7>0,L22/VD_počet_měsíců_úžívání*1.05,L22/VD_počet_měsíců_úžívání*0.95)),0) -> 0 | Q22: 0
A23: =Faktury!A16 -> 0 | C23: =Faktury!C16 -> 0 | D23: =Faktury!D16 -> 0 | E23: =Faktury!E16 -> 0 | F23: =Faktury!F16 -> 0 | G23: =Faktury!G16 -> 0 | H23: =Faktury!H16 -> 0 | I23: ='Vyúčtování byt - 1.část'!J23 -> 0 | J23: =Faktury!I16 -> 0 | K23: =IF(J23=0,0,J23*(100+Q23)/100) -> 0 | L23: ='Vyúčtování byt - 1.část'!K23 -> 0 | M23: =ROUND(I23/VD_počet_měsíců_úžívání,2) -> 0 | N23: =IF(C23="počet osob", CEILING(K23/'vstupní data'!$AJ$31/VD_počet_měsíců_úžívání*($O$7*12), 10), ROUNDUP(K23/VD_počet_měsíců_úžívání, -1)) -> 0 | O23: =CEILING(K23/'vstupní data'!$AJ$31/VD_počet_měsíců_úžívání*($O$7*12),10) -> 0 | P23: =ROUND(MAX(0,I23/VD_počet_měsíců_úžívání-IF($P$7>0,L23/VD_počet_měsíců_úžívání*1.05,L23/VD_počet_měsíců_úžívání*0.95)),0) -> 0 | Q23: 0
A24: =Faktury!A22 -> 0 | C24: =Faktury!C22 -> 0 | D24: =Faktury!D22 -> 0 | E24: =Faktury!E22 -> 0 | F24: =Faktury!F22 -> 0 | G24: =Faktury!G22 -> 0 | H24: =Faktury!H22 -> 0 | I24: ='Vyúčtování byt - 1.část'!J24 -> 0 | J24: =Faktury!I22 -> 0 | K24: =IF(J24=0,0,J24*(100+Q24)/100) -> 0 | L24: ='Vyúčtování byt - 1.část'!K24 -> 0 | M24: =ROUND(I24/VD_počet_měsíců_úžívání,2) -> 0 | N24: =IF(C24="počet osob", CEILING(K24/'vstupní data'!$AJ$31/VD_počet_měsíců_úžívání*($O$7*12), 10), ROUNDUP(K24/VD_počet_měsíců_úžívání, -1)) -> 0 | O24: =CEILING(K24/'vstupní data'!$AJ$31/VD_počet_měsíců_úžívání*($O$7*12),10) -> 0 | P24: =ROUND(MAX(0,I24/VD_počet_měsíců_úžívání-IF($P$7>0,L24/VD_počet_měsíců_úžívání*1.05,L24/VD_počet_měsíců_úžívání*0.95)),0) -> 0 | Q24: 0
A25: =Faktury!A23 -> 0 | C25: =Faktury!C23 -> 0 | D25: =Faktury!D23 -> 0 | E25: =Faktury!E23 -> 0 | F25: =Faktury!F23 -> 0 | G25: =Faktury!G23 -> 0 | H25: =Faktury!H23 -> 0 | I25: ='Vyúčtování byt - 1.část'!J25 -> 0 | J25: =Faktury!I23 -> 0 | K25: =IF(J25=0,0,J25*(100+Q25)/100) -> 0 | L25: ='Vyúčtování byt - 1.část'!K25 -> 0 | M25: =ROUND(I25/VD_počet_měsíců_úžívání,2) -> 0 | N25: =IF(C25="počet osob", CEILING(K25/'vstupní data'!$AJ$31/VD_počet_měsíců_úžívání*($O$7*12), 10), ROUNDUP(K25/VD_počet_měsíců_úžívání, -1)) -> 0 | O25: =CEILING(K25/'vstupní data'!$AJ$31/VD_počet_měsíců_úžívání*($O$7*12),10) -> 0 | P25: =ROUND(MAX(0,I25/VD_počet_měsíců_úžívání-IF($P$7>0,L25/VD_počet_měsíců_úžívání*1.05,L25/VD_počet_měsíců_úžívání*0.95)),0) -> 0 | Q25: 0
A26: =Faktury!A15 -> 0 | C26: =Faktury!C15 -> 0 | D26: =Faktury!D15 -> 0 | E26: =Faktury!E15 -> 0 | F26: =Faktury!F15 -> 0 | G26: =Faktury!G15 -> 0 | H26: =Faktury!H15 -> 0 | I26: ='Vyúčtování byt - 1.část'!J26 -> 0 | J26: =Faktury!I15 -> 0 | K26: =IF(J26=0,0,J26*(100+Q26)/100) -> 0 | L26: ='Vyúčtování byt - 1.část'!K26 -> 0 | M26: =ROUND(I26/VD_počet_měsíců_úžívání,2) -> 0 | N26: =IF(C26="počet osob", CEILING(K26/'vstupní data'!$AJ$31/VD_počet_měsíců_úžívání*($O$7*12), 10), ROUNDUP(K26/VD_počet_měsíců_úžívání, -1)) -> 0 | O26: =CEILING(K26/'vstupní data'!$AJ$31/VD_počet_měsíců_úžívání*($O$7*12),10) -> 0 | P26: =ROUND(MAX(0,I26/VD_počet_měsíců_úžívání-IF($P$7>0,L26/VD_počet_měsíců_úžívání*1.05,L26/VD_počet_měsíců_úžívání*0.95)),0) -> 0 | Q26: 0
A27: =Faktury!A13 -> 0 | C27: =Faktury!C13 -> 0 | D27: =Faktury!D13 -> 0 | E27: =Faktury!E13 -> 0 | F27: =Faktury!F13 -> 0 | G27: =Faktury!G13 -> 0 | H27: =Faktury!H13 -> 0 | I27: ='Vyúčtování byt - 1.část'!J27 -> 0 | J27: =Faktury!I13 -> 0 | K27: =IF(J27=0,0,J27*(100+Q27)/100) -> 0 | L27: ='Vyúčtování byt - 1.část'!K27 -> 0 | M27: =ROUND(I27/VD_počet_měsíců_úžívání,2) -> 0 | N27: =IF(C27="počet osob", CEILING(K27/'vstupní data'!$AJ$31/VD_počet_měsíců_úžívání*($O$7*12), 10), ROUNDUP(K27/VD_počet_měsíců_úžívání, -1)) -> 0 | O27: =CEILING(K27/'vstupní data'!$AJ$31/VD_počet_měsíců_úžívání*($O$7*12),10) -> 0 | P27: =ROUND(MAX(0,I27/VD_počet_měsíců_úžívání-IF($P$7>0,L27/VD_počet_měsíců_úžívání*1.05,L27/VD_počet_měsíců_úžívání*0.95)),0) -> 0 | Q27: 0
A28: =Faktury!A14 -> 0 | C28: =Faktury!C14 -> 0 | D28: =Faktury!D14 -> 0 | E28: =Faktury!E14 -> 0 | F28: =Faktury!F14 -> 0 | G28: =Faktury!G14 -> 0 | H28: =Faktury!H14 -> 0 | I28: ='Vyúčtování byt - 1.část'!J28 -> 0 | J28: =Faktury!I14 -> 0 | K28: =IF(J28=0,0,J28*(100+Q28)/100) -> 0 | L28: ='Vyúčtování byt - 1.část'!K28 -> 0 | M28: =ROUND(I28/VD_počet_měsíců_úžívání,2) -> 0 | N28: =IF(C28="počet osob", CEILING(K28/'vstupní data'!$AJ$31/VD_počet_měsíců_úžívání*($O$7*12), 10), ROUNDUP(K28/VD_počet_měsíců_úžívání, -1)) -> 0 | O28: =CEILING(K28/'vstupní data'!$AJ$31/VD_počet_měsíců_úžívání*($O$7*12),10) -> 0 | P28: =ROUND(MAX(0,I28/VD_počet_měsíců_úžívání-IF($P$7>0,L28/VD_počet_měsíců_úžívání*1.05,L28/VD_počet_měsíců_úžívání*0.95)),0) -> 0 | Q28: 0
A29: =Faktury!A11 -> 0 | C29: =Faktury!C11 -> 0 | D29: =Faktury!D11 -> 0 | E29: =Faktury!E11 -> 0 | F29: =Faktury!F11 -> 0 | G29: =Faktury!G11 -> 0 | H29: =Faktury!H11 -> 0 | I29: ='Vyúčtování byt - 1.část'!J29 -> 0 | J29: =Faktury!I11 -> 0 | K29: =IF(J29=0,0,J29*(100+Q29)/100) -> 0 | L29: ='Vyúčtování byt - 1.část'!K29 -> 0 | M29: =ROUND(I29/VD_počet_měsíců_úžívání,2) -> 0 | N29: =IF(C29="počet osob", CEILING(K29/'vstupní data'!$AJ$31/VD_počet_měsíců_úžívání*($O$7*12), 10), ROUNDUP(K29/VD_počet_měsíců_úžívání, -1)) -> 0 | O29: =CEILING(K29/'vstupní data'!$AJ$31/VD_počet_měsíců_úžívání*($O$7*12),10) -> 0 | P29: =ROUND(MAX(0,I29/VD_počet_měsíců_úžívání-IF($P$7>0,L29/VD_počet_měsíců_úžívání*1.05,L29/VD_počet_měsíců_úžívání*0.95)),0) -> 0 | Q29: 0
A30: Celkem náklady na odběrná místa | E30: =SUM(E10:E29) -> 0 | G30: Celkem vyúčtování: | I30: =SUM(I10:I29) -> 0 | J30: =SUM(J10:J29) -> 0 | K30: =SUM(K10:K29) -> 0 | M30: =SUM(M10:M29) -> 0 | N30: =SUM(N10:N29) -> 0 | P30: =SUM(P10:P29) -> 0
G31: Měsíčně včetně fondu oprav | M31: =M30+A36/VD_počet_měsíců_úžívání -> 0 | N31: =N30+A36/VD_počet_měsíců_úžívání -> 0 | O31: Rozdíl měsíčně | P31: =ROUND(P30-M30,0) -> 0 | Q31: * mění se pouze položky této barvy zbytek systém počítá sám, navýšení % nastavujeme až do akceptovatelného preplatku
O32: Kontrola | P32: =P31-P7 -> 0
A33: Pevné platby
A34: ='Vyúčtování byt - 1.část'!A35 -> 0
A35: Celkem za rok
A36: ='Vyúčtování byt - 1.část'!B35 -> 0 | K36: KONTROLA
A37: Výsledek vyúčtování | K37: Zálohy před změnou | M37: =M31 -> 0 | N37: *udělat kontrolu s OS zda sedí
A38: =ROUND('Vyúčtování byt - 1.část'!K31,0) -> 0 | K38: Záloha po změně | M38: =N31 -> 0
K39: Rozdíl měsíčně | M39: =M38-M37 -> 0 | N39: =M39*VD_počet_měsíců_úžívání+'Vyúčtování byt - 1.část'!VB_preplatky_celkem -> 0 | O39: *kontrola zda vychází stejněj jako budoucí přeplatek
K40: Náklad za poslední vyúčtování | M40: =J30 -> 0
K41: Teoretický náklad po změně | M41: =N30*VD_počet_měsíců_úžívání -> 0
...

Sheet Seznam
A1: MENU
A2: VÝSTUPY | B2: MĚŘIDLA A DATA | C2: EVIDENCE | D2: EXPORT | E2: KONTROLA
A3: Vstupní data | B3: Vodoměry TUV | C3: Evidence | D3: Export send mail | E3: Výpočet vyúčtování
A4: Vyúčtování | B4: Vodoměry SV | C4: Úhrady | D4: Bytové domy
A5: Příjem SVJ včetně výdajů | B5: Teplo | C5: Přeplatky a nedoplatky | D5: Odečty formulář
A6: Příjem SVJ bez výdajů | B6: Elektroměry | C6: Předpisy - výpočet
A7: Náklady za dům | B7: Výtahy
A8: Rozpočet domu | B8: Počet osob
A9: Parametry | B9: Předpisy po měsící
A10: Faktury | B10: Faktury za služby

Sheet Vyúčtování byt - 1.část
C1: =IF('vstupní data'!B34="AdminReal, s.r.o.","AdminReal s.r.o., Veveří 2581/102 , 616 00 Brno, IČO 02827476, Zapsáno KS v Brně, oddíl C, vložka 82606","BrnoReal s.r.o., Veveří 2581/102 , 616 00 Brno, IČO 14423537, Zapsáno KS v Brně, oddíl C, vložka 128255") -> 0 | J1: =IF('vstupní data'!$B$34="BrnoReal, s.r.o.",'vstupní data'!$B$60,'vstupní data'!$B$59) -> 0
A2: ='vstupní data'!B5 -> 0 | M2: MENU
A3: adresa společenství: | C3: =dum_adresa -> 0 | F3: bankovní spojení člena: | H3: ='vstupní data'!B7 -> 0 | J3: č. prostoru: | K3: ='vstupní data'!B4 -> 0
A4: bankovní spojení společenství: | C4: ='vstupní data'!B35 -> 0 | E4: variabilní symbol pro platbu nedoplatku: | H4: ='vstupní data'!B6 -> 0 | J4: zůčtovací období: | K4: =VLOOKUP(BYT,Evidence!$A:$Z,18,0) -> 0
A6: =("Vyúčtování služeb: "&'vstupní data'!B12&"") -> 0
E8: Odběrné místo (dům) | H8: Uživatel
A9: Položka | B9: Sloupec1 | C9: Jednotka | D9: Podíl | E9: Náklad | F9: Jednotek | G9: Kč/jedn | H9: Jednotek2 | I9: Náklad2 | J9: Záloha | K9: Přeplatky|nedoplatky
A10: =Faktury!A4 -> 0 | C10: =Faktury!C4 -> 0 | D10: =Faktury!D4 -> 0 | E10: =Faktury!E4 -> 0 | F10: =Faktury!F4 -> 0 | G10: =Faktury!G4 -> 0 | H10: =Faktury!H4 -> 0 | I10: =Faktury!I4 -> 0 | J10: =Faktury!J4 -> 0 | K10: =Faktury!K4 -> 0
A11: =Faktury!A5 -> 0 | C11: =Faktury!C5 -> 0 | D11: =Faktury!D5 -> 0 | E11: =Faktury!E5 -> 0 | F11: =Faktury!F5 -> 0 | G11: =Faktury!G5 -> 0 | H11: =Faktury!H5 -> 0 | I11: =Faktury!I5 -> 0 | J11: =Faktury!J5 -> 0 | K11: =Faktury!K5 -> 0
A12: =Faktury!A6 -> 0 | C12: =Faktury!C6 -> 0 | D12: =Faktury!D6 -> 0 | E12: =Faktury!E6 -> 0 | F12: =Faktury!F6 -> 0 | G12: =Faktury!G6 -> 0 | H12: =Faktury!H6 -> 0 | I12: =Faktury!I6 -> 0 | J12: =Faktury!J6 -> 0 | K12: =Faktury!K6 -> 0
A13: =Faktury!A7 -> 0 | C13: =Faktury!C7 -> 0 | D13: =Faktury!D7 -> 0 | E13: =Faktury!E7 -> 0 | F13: =Faktury!F7 -> 0 | G13: =Faktury!G7 -> 0 | H13: =Faktury!H7 -> 0 | I13: =Faktury!I7 -> 0 | J13: =Faktury!J7 -> 0 | K13: =Faktury!K7 -> 0
A14: =Faktury!A17 -> 0 | C14: =Faktury!C17 -> 0 | D14: =Faktury!D17 -> 0 | E14: =Faktury!E17 -> 0 | F14: =Faktury!F17 -> 0 | G14: =Faktury!G17 -> 0 | H14: =Faktury!H17 -> 0 | I14: =Faktury!I17 -> 0 | J14: =Faktury!J17 -> 0 | K14: =Faktury!K17 -> 0
A15: =Faktury!A12 -> 0 | C15: =Faktury!C12 -> 0 | D15: =Faktury!D12 -> 0 | E15: =Faktury!E12 -> 0 | F15: =Faktury!F12 -> 0 | G15: =Faktury!G12 -> 0 | H15: =Faktury!H12 -> 0 | I15: =Faktury!I12 -> 0 | J15: =Faktury!J12 -> 0 | K15: =Faktury!K12 -> 0
A16: =Faktury!A9 -> 0 | C16: =Faktury!C9 -> 0 | D16: =Faktury!D9 -> 0 | E16: =Faktury!E9 -> 0 | F16: =Faktury!F9 -> 0 | G16: =Faktury!G9 -> 0 | H16: =Faktury!H9 -> 0 | I16: =Faktury!I9 -> 0 | J16: =Faktury!J9 -> 0 | K16: =Faktury!K9 -> 0
A17: =Faktury!A2 -> 0 | C17: =Faktury!C2 -> 0 | D17: =Faktury!D2 -> 0 | E17: =Faktury!E2 -> 0 | F17: =Faktury!F2 -> 0 | G17: =Faktury!G2 -> 0 | H17: =Faktury!H2 -> 0 | I17: =Faktury!I2 -> 0 | J17: =Faktury!J2 -> 0 | K17: =Faktury!K2 -> 0
A18: =Faktury!A3 -> 0 | C18: =Faktury!C3 -> 0 | D18: =Faktury!D3 -> 0 | E18: =Faktury!E3 -> 0 | F18: =Faktury!F3 -> 0 | G18: =Faktury!G3 -> 0 | H18: =Faktury!H3 -> 0 | I18: =Faktury!I3 -> 0 | J18: =Faktury!J3 -> 0 | K18: =Faktury!K3 -> 0
A19: =Faktury!A19 -> 0 | C19: =Faktury!C19 -> 0 | D19: =Faktury!D19 -> 0 | E19: =Faktury!E19 -> 0 | F19: =Faktury!F19 -> 0 | G19: =Faktury!G19 -> 0 | H19: =Faktury!H19 -> 0 | I19: =Faktury!I19 -> 0 | J19: =Faktury!J19 -> 0 | K19: =Faktury!K19 -> 0
A20: =Faktury!A18 -> 0 | C20: =Faktury!C18 -> 0 | D20: =Faktury!D18 -> 0 | E20: =Faktury!E18 -> 0 | F20: =Faktury!F18 -> 0 | G20: =Faktury!G18 -> 0 | H20: =Faktury!H18 -> 0 | I20: =Faktury!I18 -> 0 | J20: =Faktury!J18 -> 0 | K20: =Faktury!K18 -> 0
A21: =Faktury!A10 -> 0 | C21: =Faktury!C10 -> 0 | D21: =Faktury!D10 -> 0 | E21: =Faktury!E10 -> 0 | F21: =Faktury!F10 -> 0 | G21: =Faktury!G10 -> 0 | H21: =Faktury!H10 -> 0 | I21: =Faktury!I10 -> 0 | J21: =Faktury!J10 -> 0 | K21: =Faktury!K10 -> 0
A22: =Faktury!A8 -> 0 | C22: =Faktury!C8 -> 0 | D22: =Faktury!D8 -> 0 | E22: =Faktury!E8 -> 0 | F22: =Faktury!F8 -> 0 | G22: =Faktury!G8 -> 0 | H22: =Faktury!H8 -> 0 | I22: =Faktury!I8 -> 0 | J22: =Faktury!J8 -> 0 | K22: =Faktury!K8 -> 0
A23: =Faktury!A16 -> 0 | C23: =Faktury!C16 -> 0 | D23: =Faktury!D16 -> 0 | E23: =Faktury!E16 -> 0 | F23: =Faktury!F16 -> 0 | G23: =Faktury!G16 -> 0 | H23: =Faktury!H16 -> 0 | I23: =Faktury!I16 -> 0 | J23: =Faktury!J16 -> 0 | K23: =Faktury!K16 -> 0
A24: =Faktury!A22 -> 0 | C24: =Faktury!C22 -> 0 | D24: =Faktury!D22 -> 0 | E24: =Faktury!E22 -> 0 | F24: =Faktury!F22 -> 0 | G24: =Faktury!G22 -> 0 | H24: =Faktury!H22 -> 0 | I24: =Faktury!I22 -> 0 | J24: =Faktury!J22 -> 0 | K24: =Faktury!K22 -> 0
A25: =Faktury!A23 -> 0 | C25: =Faktury!C23 -> 0 | D25: =Faktury!D23 -> 0 | E25: =Faktury!E23 -> 0 | F25: =Faktury!F23 -> 0 | G25: =Faktury!G23 -> 0 | H25: =Faktury!H23 -> 0 | I25: =Faktury!I23 -> 0 | J25: =Faktury!J23 -> 0 | K25: =Faktury!K23 -> 0
A26: =VLOOKUP(BYT,Parametry!1:1048576,2,1) -> 0 | C26: =VLOOKUP(BYT,Parametry!1:1048576,3,1) -> 0 | D26: =VLOOKUP(BYT,Parametry!1:1048576,4,1) -> 0 | E26: =VLOOKUP(BYT,Parametry!1:1048576,5,1) -> 0 | F26: =VLOOKUP(BYT,Parametry!1:1048576,6,1) -> 0 | G26: =VLOOKUP(BYT,Parametry!1:1048576,7,1) -> 0 | H26: =VLOOKUP(BYT,Parametry!1:1048576,8,1) -> 0 | I26: =VLOOKUP(BYT,Parametry!1:1048576,9,1) -> 0 | J26: 0 | K26: =VLOOKUP(BYT,Parametry!1:1048576,11,1) -> 0
A27: =Faktury!A13 -> 0 | C27: =Faktury!C13 -> 0 | D27: =Faktury!D13 -> 0 | E27: =Faktury!E13 -> 0 | F27: =Faktury!F13 -> 0 | G27: =Faktury!G13 -> 0 | H27: =Faktury!H13 -> 0 | I27: =Faktury!I13 -> 0 | J27: =Faktury!J13 -> 0 | K27: =Faktury!K13 -> 0
A28: =Faktury!A14 -> 0 | C28: =Faktury!C14 -> 0 | D28: =Faktury!D14 -> 0 | E28: =Faktury!E14 -> 0 | F28: =Faktury!F14 -> 0 | G28: =Faktury!G14 -> 0 | H28: =Faktury!H14 -> 0 | I28: =Faktury!I14 -> 0 | J28: =Faktury!J14 -> 0 | K28: =Faktury!K14 -> 0
A29: =Faktury!A11 -> 0 | C29: =Faktury!C11 -> 0 | D29: =Faktury!D11 -> 0 | E29: =Faktury!E11 -> 0 | F29: =Faktury!F11 -> 0 | G29: =Faktury!G11 -> 0 | H29: =Faktury!H11 -> 0 | I29: =Faktury!I11 -> 0 | J29: =Faktury!J11 -> 0 | K29: =Faktury!K11 -> 0
A30: =Faktury!A21 -> 0 | C30: =Faktury!C21 -> 0 | D30: =Faktury!D21 -> 0 | E30: =Faktury!E21 -> 0 | F30: =Faktury!F21 -> 0 | G30: =Faktury!G21 -> 0 | H30: =Faktury!H21 -> 0 | I30: =Faktury!I21 -> 0 | J30: =Faktury!J21 -> 0 | K30: =Faktury!K21 -> 0
A31: Celkem náklady na odběrná místa | E31: =SUM(E10:E30) -> 0 | G31: Celkem vyúčtování: | I31: =SUM(I10:I30) -> 0 | J31: =SUM(J10:J30) -> 0 | K31: =SUM(K10:K30) -> 0
C32: =IF(ExcelMacroData!C15=TRUE,_xlfn.IMAGE(ExcelMacroData!C16),"") -> 0 | G32: =IF(K32<0,"Nedoplatek v účtovaném období",IF(K32>0,"Přeplatek v účtovaném období",IF(K32=0,"Není evidován v účtovaném období přeplatek ani nedoplatek"))) -> 0 | K32: =VD_přeplatek_aktuální_rok -> 0
G33: =IF(K33<0,"Nedoplatek v minulém období",IF(K33>0,"Přeplatek v minulém období",IF(K33=0,"Není evidován v minulém období přeplatek ani nedoplatek"))) -> 0 | K33: =VLOOKUP(BYT,'Přeplatky nedoplatky'!$A:$E,5,0) -> 0
A34: Pevné platby | B34: Celkem za rok | G34: =IF('Vyúčtování byt - 1.část'!K34<0,"NEDOPLATEK CELKEM",IF('Vyúčtování byt - 1.část'!K34>0,"PŘEPLATEK CELKEM",IF('Vyúčtování byt - 1.část'!K34=0,"Nemáte přeplatek ani nedoplatek"))) -> 0 | K34: =ROUND(K31+K32+K33,0) -> 0
A35: =INDEX(Faktury!A2:A53,MATCH("*Fond*",Faktury!A2:A53,0)) -> 0 | B35: ='vstupní data'!R17 -> 0 | E35: =IF(VD_účet_vlastníka=0,(IF('vstupní data'!C11<0,"Nedoplatek uhraďte na účet číslo: "&VD_číslo_účtu_SVJ&", variabilní symbol "&VD_VS&"",IF('vstupní data'!C11>0,"Přeplatek Vám bude vyplacen poštovní poukázkou",IF('vstupní data'!C11=0,"""Nemáte žádný přeplatek ani nedoplatek")))),IF('vstupní data'!C11<0,"Nedoplatek uhraďte na účet číslo: "&VD_číslo_účtu_SVJ&", variabilní symbol "&VD_VS&"",IF('vstupní data'!C11>0,"Přeplatek Vám bude vyplacen na číslo účtu "&VD_účet_vlastníka&"",IF('vstupní data'!C11=0,"Nemáte žádný přeplatek ani nedoplatek")))) -> 0
A37: ="Přehled úhrad za rok "&'vstupní data'!B12&"" -> 0
A38: ="1/"&'vstupní data'!$B$12&"" -> 0 | B38: ="2/"&'vstupní data'!$B$12&"" -> 0 | C38: ="3/"&'vstupní data'!$B$12&"" -> 0 | D38: ="4/"&'vstupní data'!$B$12&"" -> 0 | E38: ="5/"&'vstupní data'!$B$12&"" -> 0 | F38: ="6/"&'vstupní data'!$B$12&"" -> 0 | G38: ="7/"&'vstupní data'!$B$12&"" -> 0 | H38: ="8/"&'vstupní data'!$B$12&"" -> 0 | I38: ="9/"&'vstupní data'!$B$12&"" -> 0 | J38: ="10/"&'vstupní data'!$B$12&"" -> 0 | K38: ="11/"&'vstupní data'!$B$12&"" -> 0 | L38: ="12/"&'vstupní data'!$B$12&"" -> 0
A39: ='vstupní data'!N19 -> 0 | B39: ='vstupní data'!N20 -> 0 | C39: ='vstupní data'!N21 -> 0 | D39: ='vstupní data'!N22 -> 0 | E39: ='vstupní data'!N23 -> 0 | F39: ='vstupní data'!N24 -> 0 | G39: ='vstupní data'!N25 -> 0 | H39: ='vstupní data'!N26 -> 0 | I39: ='vstupní data'!N27 -> 0 | J39: ='vstupní data'!N28 -> 0 | K39: ='vstupní data'!N29 -> 0 | L39: ='vstupní data'!N30 -> 0
A40: ="Přehled předpisů za rok "&'vstupní data'!B12&"" -> 0
A41: ="1/"&'vstupní data'!$B$12&"" -> 0 | B41: ="2/"&'vstupní data'!$B$12&"" -> 0 | C41: ="3/"&'vstupní data'!$B$12&"" -> 0 | D41: ="4/"&'vstupní data'!$B$12&"" -> 0 | E41: ="5/"&'vstupní data'!$B$12&"" -> 0 | F41: ="6/"&'vstupní data'!$B$12&"" -> 0 | G41: ="7/"&'vstupní data'!$B$12&"" -> 0 | H41: ="8/"&'vstupní data'!$B$12&"" -> 0 | I41: ="9/"&'vstupní data'!$B$12&"" -> 0 | J41: ="10/"&'vstupní data'!$B$12&"" -> 0 | K41: ="11/"&'vstupní data'!$B$12&"" -> 0 | L41: ="12/"&'vstupní data'!$B$12&"" -> 0
A42: ='vstupní data'!Q19 -> 0 | B42: ='vstupní data'!Q20 -> 0 | C42: ='vstupní data'!Q21 -> 0 | D42: ='vstupní data'!Q22 -> 0 | E42: ='vstupní data'!Q23 -> 0 | F42: ='vstupní data'!Q24 -> 0 | G42: ='vstupní data'!Q25 -> 0 | H42: ='vstupní data'!Q26 -> 0 | I42: ='vstupní data'!Q27 -> 0 | J42: ='vstupní data'!Q28 -> 0 | K42: ='vstupní data'!Q29 -> 0 | L42: ='vstupní data'!Q30 -> 0
A43: =IF('vstupní data'!B11=0,"K úhradě za rok",IF('vstupní data'!B11<0,"Nedoplatek za rok celkem",IF('vstupní data'!B11>0,"Přeplatek za rok celkem",IF('vstupní data'!B11=0,"")))) -> 0 | C43: ='vstupní data'!B11 -> 0
...

Sheet vstupní data
A1: Vstupní data
E2: Vysvětlivky polí(adres)
A3: Název - Bytový dům | B3: =C3 -> 0 | C3: Společenství vlastníků pro dům Neptun | D3: Kníničky č.ev. 318, 635 00 Brno | E3: vp_ - vyhledávací pole - následuje jméno listu kde je
A4: Jednotka | B4: =Evidence!A2 -> 0 | C4: =SUBSTITUTE(SUBSTITUTE(SUBSTITUTE(BYT," ","-"),"---","-"),"/","") -> 0 | E4: VD_ vstupní dat, na začátku vždy zkratka listu
A5: Jméno | B5: =VLOOKUP(BYT,Evidence!$A:$Z,2,0) -> 0 | C5: =IF(D5="paní","Vážená","Vážený") -> 0 | D5: =(IF(RIGHT(B5,1)="á","paní","pane")) -> 0 | E5: =LEFT(VD_jméno,FIND(" ",B5)-1) -> 0 | F5: =TRIM(RIGHT(SUBSTITUTE(VD_jméno," ",REPT(" ",100)),100)) -> 0
A6: Variabilní symbol | B6: =VLOOKUP(BYT,Evidence!1:1048576,22,0) -> 0 | C6: *vs je s devitkami na konci kvuli platbe
A7: bankovní spojení (účet) vlastníka bytu | B7: =VLOOKUP(BYT,Evidence!$A:$Z,11,0) -> 0 | L7: Úhrada dle delky vlastnictví | P7: Předpisy | R7: FO
A8: vyúčtovací období | B8: ="1.1."&'vstupní data'!$B$12&" - 1.12."&'vstupní data'!$B$12&"" -> 0 | F8: Platby záloh | H8: Předpis záloh | J8: Rozdíl | L8: Datum pro vypočet | M8: =VLOOKUP(BYT,Evidence!$A:$T,16,1) -> 0 | N8: =VLOOKUP(BYT,Evidence!$A:$T,17,1) -> 0
A9: Výsledek vyúčtování | F9: OD | G9: DO zbytek roku | H9: OD | I9: DO zbytek roku | J9: OD | K9: DO | L9: Převod na číslo sloupce | M9: =MONTH(M8) -> 0 | N9: =MONTH(N8) -> 0 | O9: 12 | P9: vzorec na změnu měsíců dle vlastnictví
A10: Přeplatek/nedoplatek z minulého období | B10: =VLOOKUP(BYT,'Přeplatky nedoplatky'!$A:$E,5,0) -> 0 | F10: =ADDRESS(MATCH('vstupní data'!$B$4,uhrady!A:A,0),2,4,1) -> 0 | G10: =ADDRESS((MATCH('vstupní data'!$B$4,uhrady!A:A,0)),(MATCH($B$15,'Předpis po mesici'!$B$2:$M$2,0)+1),4) -> 0 | H10: =ADDRESS(MATCH('vstupní data'!$B$4,'Předpis po mesici'!A:A,0),262,4,1) -> 0 | I10: =ADDRESS((MATCH('vstupní data'!$B$4,'Předpis po mesici'!A:A,0)),(MATCH($B$15,'Předpis po mesici'!$JC$2:$JN$2,0)+262),4) -> 0 | J10: =F11-H11 -> 0 | K10: =G11-I11 -> 0 | L10: Převod na písmeno sloupce | M10: =SUBSTITUTE(ADDRESS(1,M9+1,4),"1","") -> 0 | N10: =SUBSTITUTE(ADDRESS(1,N9+1,4),"1","") -> 0 | P10: =SUBSTITUTE(ADDRESS(1,M9+262,4),"1","") -> 0 | Q10: =SUBSTITUTE(ADDRESS(1,N9+262,4),"1","") -> 0 | R10: =SUBSTITUTE(ADDRESS(1,M9+79,4),"1","") -> 0 | S10: =SUBSTITUTE(ADDRESS(1,N9+79,4),"1","") -> 0
A11: Přeplatky/nedoplatky v aktuálním roce | B11: =SUM(N19:N30)-SUM(Q19:Q30) -> 0 | C11: ='Vyúčtování byt - 1.část'!VB_preplatky_celkem -> 0 | D11: =SUM(VD_přeplatek_z_minula+VD_přeplatek_aktuální_rok+C11) -> 0 | F11: =_xlfn.IFNA(SUM(INDIRECT("'uhrady'!"&F10&":"&G10)),0) -> 0 | G11: =LOOKUP(B4,uhrady!A:A,uhrady!N:N)-F11 -> 0 | H11: =_xlfn.IFNA(SUM(INDIRECT("'Předpis po mesici'!"&H10&":"&I10)),0) -> 0 | I11: =LOOKUP(B4,'Předpis po mesici'!A:A,'Předpis po mesici'!JO:JO)-H11 -> 0 | L11: Pořet měsíců-pro kontrolu | M11: =N9-M9+1 -> 0
A12: Za rok | B12: 2024 | F12: Platba FO | L12: Řádek vybraneho bytu | M12: ="uhrady!"&ADDRESS(MATCH(BYT,uhrady!A:A,0),2,4,1) -> 0 | N12: =ROW(INDIRECT(M12)) -> 0 | P12: ="'Předpis po mesici'!"&ADDRESS(MATCH(BYT,'Předpis po mesici'!A:A,0),2,4,1) -> 0 | Q12: =ROW(INDIRECT(P12)) -> 0 | R12: ="'Předpis po mesici'!"&ADDRESS(MATCH(BYT,'Předpis po mesici'!A:A,0),2,4,1) -> 0 | S12: =ROW(INDIRECT(R12)) -> 0
A13: Cena BVak | B13: 105,53 | F13: =ADDRESS(MATCH('vstupní data'!$B$4,'Předpis po mesici'!A:A,0),80,4,1) -> 0 | G13: =ADDRESS((MATCH('vstupní data'!$B$4,'Předpis po mesici'!A:A,0)),(MATCH($B$15,'Předpis po mesici'!$B$2:$M$2,0)+79),4) -> 0
C14: Zbylé měsíce | D14: Čas | F14: =_xlfn.IFNA(SUM(INDIRECT("'Předpis po mesici'!"&F13&":"&G13)),0) -> 0 | G14: =LOOKUP(B4,'Předpis po mesici'!A:A,'Předpis po mesici'!CN:CN)-F14 -> 0 | L14: Adresa bunek pro součet | M14: =M10&$N12 -> 0 | N14: =N10&$N12 -> 0 | P14: =P10&$Q12 -> 0 | Q14: =Q10&$Q12 -> 0 | R14: =R10&$S12 -> 0 | S14: =S10&$S12 -> 0
A15: Počet měsíců (užíváno majitelem) | B15: =M11 -> 0 | C15: =12-B15 -> 0 | D15: první část roku | L15: Finální adresa pro součet | M15: ="uhrady!"&_xlfn.CONCAT(M14,":",N14) -> 0 | P15: ="'Předpis po mesici'!"&_xlfn.CONCAT(P14,":",Q14) -> 0 | R15: ="'Předpis po mesici'!"&_xlfn.CONCAT(R14,":",S14) -> 0
C16: První část roku | F16: Druhá část roku
A17: Počet jednotek | B17: 23 | C17: ="1.1."&'vstupní data'!B12&"" -> 0 | D17: =EDATE(C17,B15)-1 -> 0 | E17: =(""&'vstupní data'!C18&" - "&'vstupní data'!D18&"") -> 0 | F17: =EDATE(C17,B15) -> 0 | G17: =EDATE(D17,C15) -> 0 | H17: =(""&'vstupní data'!F18&" - "&'vstupní data'!G18&"") -> 0 | L17: Finání součet | M17: =SUM(INDIRECT(M15)) -> 0 | P17: =SUM(INDIRECT(P15)) -> 0 | R17: =SUM(INDIRECT(R15)) -> 0
A18: Užitná plocha domu - celková | B18: 1423.8 | C18: =""&TEXT(C17,"d.m.rrrr") -> 0 | D18: =""&TEXT(D17,"d.m.rrrr") -> 0 | F18: =""&TEXT(F17,"d.m.rrrr") -> 0 | G18: =""&TEXT(G17,"d.m.rrrr") -> 0 | M18: Úhrady | P18: Měsíc | Q18: Předpisy celkem | R18: Měsíc | S18: =("Služby "&'vstupní data'!B4&"") -> 0
A19: Užitná plocha domu - započitatelná | B19: 0 | L19: Platby jednotlivě | M19: 1 | N19: =IF(AND(M19>=$M$9,M19<=$O$9),VLOOKUP(BYT,uhrady!$A$2:$M$102,M19+1,FALSE),0) -> 0 | P19: 1 | Q19: =IF(AND(P19>=$M$9,P19<=$O$9),VLOOKUP(BYT,'Předpis po mesici'!$A$3:$JQ$102,P19+262,FALSE),0) -> 0 | R19: 1 | S19: =IF(AND(P19>=$M$9,P19<=$N$9),VLOOKUP(BYT,'Předpis po mesici'!$A$3:$JQ$102,P19+79,FALSE),0) -> 0 | T19: =IF(AND(P19>=$M$9,P19<=$N$9),VLOOKUP(BYT,'Předpis po mesici'!$A$3:$JQ$102,P19+1,FALSE),0) -> 0 | U19: =IF(AND(P19>=$M$9,P19<=$N$9),VLOOKUP(BYT,'Předpis po mesici'!$A$3:$JQ$102,P19+14,FALSE),0) -> 0 | V19: =IF(AND(P19>=$M$9,P19<=$N$9),VLOOKUP(BYT,'Předpis po mesici'!$A$3:$JQ$102,P19+27,FALSE),0) -> 0 | W19: =IF(AND(P19>=$M$9,P19<=$N$9),VLOOKUP(BYT,'Předpis po mesici'!$A$3:$JQ$102,P19+40,FALSE),0) -> 0 | X19: =IF(AND(P19>=$M$9,P19<=$N$9),VLOOKUP(BYT,'Předpis po mesici'!$A$3:$JQ$102,P19+53,FALSE),0) -> 0 | Y19: =IF(AND(P19>=$M$9,P19<=$N$9),VLOOKUP(BYT,'Předpis po mesici'!$A$3:$JQ$102,P19+66,FALSE),0) -> 0 | Z19: =IF(AND(P19>=$M$9,P19<=$N$9),VLOOKUP(BYT,'Předpis po mesici'!$A$3:$JQ$102,P19+92,FALSE),0) -> 0 | AA19: =IF(AND(P19>=$M$9,P19<=$N$9),VLOOKUP(BYT,'Předpis po mesici'!$A$3:$JQ$102,P19+105,FALSE),0) -> 0 | AB19: =IF(AND(P19>=$M$9,P19<=$N$9),VLOOKUP(BYT,'Předpis po mesici'!$A$3:$JQ$102,P19+118,FALSE),0) -> 0 | AC19: =IF(AND(P19>=$M$9,P19<=$N$9),VLOOKUP(BYT,'Předpis po mesici'!$A$3:$JQ$102,P19+131,FALSE),0) -> 0 | AD19: =IF(AND(P19>=$M$9,P19<=$N$9),VLOOKUP(BYT,'Předpis po mesici'!$A$3:$JQ$102,P19+170,FALSE),0) -> 0 | AE19: =IF(AND(P19>=$M$9,P19<=$N$9),VLOOKUP(BYT,'Předpis po mesici'!$A$3:$JQ$102,P19+183,FALSE),0) -> 0 | AF19: =IF(AND(P19>=$M$9,P19<=$N$9),VLOOKUP(BYT,'Předpis po mesici'!$A$3:$JQ$102,P19+196,FALSE),0) -> 0 | AG19: =IF(AND(P19>=$M$9,P19<=$N$9),VLOOKUP(BYT,'Předpis po mesici'!$A$3:$JQ$102,P19+209,FALSE),0) -> 0 | AH19: =IF(AND(P19>=$M$9,P19<=$N$9),VLOOKUP(BYT,'Předpis po mesici'!$A$3:$JQ$102,P19+222,FALSE),0) -> 0 | AI19: =IF(AND(P19>=$M$9,P19<=$N$9),VLOOKUP(BYT,'Předpis po mesici'!$A$3:$JQ$102,P19+157,FALSE),0) -> 0 | AJ19: =IF(AND(P19>=$M$9,P19<=$N$9),VLOOKUP(BYT,'Počet osob'!$A$2:$JR$102,P19+2,FALSE),0) -> 0 | AK19: =IF(AND(P19>=$M$9,P19<=$N$9),VLOOKUP(BYT,'Předpis po mesici'!$A$3:$JQ$102,P19+144,FALSE),0) -> 0 | AL19: =IF(AND(P19>=$M$9,P19<=$N$9),VLOOKUP(BYT,'Předpis po mesici'!$A$3:$JQ$102,P19+248,FALSE),0) -> 0 | AM19: =IF(AND(P19>=$M$9,P19<=$N$9),VLOOKUP(BYT,'Předpis po mesici'!$A$3:$JQ$102,P19+235,FALSE),0) -> 0 | AN19: =IF(AND(P19>=$M$9,P19<=$N$9),VLOOKUP(BYT,'Předpis po mesici'!$A$3:$JQ$102,P19+235,FALSE),0) -> 0
A20: Počet komínů | B20: =Evidence!F104 -> 0 | M20: 2 | N20: =IF(AND(M20>=$M$9,M20<=$O$9),VLOOKUP(BYT,uhrady!$A$2:$M$102,M20+1,FALSE),0) -> 0 | P20: 2 | Q20: =IF(AND(P20>=$M$9,P20<=$O$9),VLOOKUP(BYT,'Předpis po mesici'!$A$3:$JQ$102,P20+262,FALSE),0) -> 0 | R20: 2 | S20: =IF(AND(P20>=$M$9,P20<=$N$9),VLOOKUP(BYT,'Předpis po mesici'!$A$3:$JQ$102,P20+79,FALSE),0) -> 0 | T20: =IF(AND(P20>=$M$9,P20<=$N$9),VLOOKUP(BYT,'Předpis po mesici'!$A$3:$JQ$102,P20+1,FALSE),0) -> 0 | U20: =IF(AND(P20>=$M$9,P20<=$N$9),VLOOKUP(BYT,'Předpis po mesici'!$A$3:$JQ$102,P20+14,FALSE),0) -> 0 | V20: =IF(AND(P20>=$M$9,P20<=$N$9),VLOOKUP(BYT,'Předpis po mesici'!$A$3:$JQ$102,P20+27,FALSE),0) -> 0 | W20: =IF(AND(P20>=$M$9,P20<=$N$9),VLOOKUP(BYT,'Předpis po mesici'!$A$3:$JQ$102,P20+40,FALSE),0) -> 0 | X20: =IF(AND(P20>=$M$9,P20<=$N$9),VLOOKUP(BYT,'Předpis po mesici'!$A$3:$JQ$102,P20+53,FALSE),0) -> 0 | Y20: =IF(AND(P20>=$M$9,P20<=$N$9),VLOOKUP(BYT,'Předpis po mesici'!$A$3:$JQ$102,P20+66,FALSE),0) -> 0 | Z20: =IF(AND(P20>=$M$9,P20<=$N$9),VLOOKUP(BYT,'Předpis po mesici'!$A$3:$JQ$102,P20+92,FALSE),0) -> 0 | AA20: =IF(AND(P20>=$M$9,P20<=$N$9),VLOOKUP(BYT,'Předpis po mesici'!$A$3:$JQ$102,P20+105,FALSE),0) -> 0 | AB20: =IF(AND(P20>=$M$9,P20<=$N$9),VLOOKUP(BYT,'Předpis po mesici'!$A$3:$JQ$102,P20+118,FALSE),0) -> 0 | AC20: =IF(AND(P20>=$M$9,P20<=$N$9),VLOOKUP(BYT,'Předpis po mesici'!$A$3:$JQ$102,P20+131,FALSE),0) -> 0 | AD20: =IF(AND(P20>=$M$9,P20<=$N$9),VLOOKUP(BYT,'Předpis po mesici'!$A$3:$JQ$102,P20+170,FALSE),0) -> 0 | AE20: =IF(AND(P20>=$M$9,P20<=$N$9),VLOOKUP(BYT,'Předpis po mesici'!$A$3:$JQ$102,P20+183,FALSE),0) -> 0 | AF20: =IF(AND(P20>=$M$9,P20<=$N$9),VLOOKUP(BYT,'Předpis po mesici'!$A$3:$JQ$102,P20+196,FALSE),0) -> 0 | AG20: =IF(AND(P20>=$M$9,P20<=$N$9),VLOOKUP(BYT,'Předpis po mesici'!$A$3:$JQ$102,P20+209,FALSE),0) -> 0 | AH20: =IF(AND(P20>=$M$9,P20<=$N$9),VLOOKUP(BYT,'Předpis po mesici'!$A$3:$JQ$102,P20+222,FALSE),0) -> 0 | AI20: =IF(AND(P20>=$M$9,P20<=$N$9),VLOOKUP(BYT,'Předpis po mesici'!$A$3:$JQ$102,P20+157,FALSE),0) -> 0 | AJ20: =IF(AND(P20>=$M$9,P20<=$N$9),VLOOKUP(BYT,'Počet osob'!$A$2:$JR$102,P20+2,FALSE),0) -> 0 | AK20: =IF(AND(P20>=$M$9,P20<=$N$9),VLOOKUP(BYT,'Předpis po mesici'!$A$3:$JQ$102,P20+144,FALSE),0) -> 0 | AL20: =IF(AND(P20>=$M$9,P20<=$N$9),VLOOKUP(BYT,'Předpis po mesici'!$A$3:$JQ$102,P20+248,FALSE),0) -> 0 | AM20: =IF(AND(P20>=$M$9,P20<=$N$9),VLOOKUP(BYT,'Předpis po mesici'!$A$3:$JQ$102,P20+235,FALSE),0) -> 0 | AN20: =IF(AND(P20>=$M$9,P20<=$N$9),VLOOKUP(BYT,'Předpis po mesici'!$A$3:$JQ$102,P20+235,FALSE),0) -> 0
A21: Počet osob (celkem/výtah) | B21: ='Počet osob'!O104 -> 0 | C21: ='Počet osob'!P104 -> 0 | M21: 3 | N21: =IF(AND(M21>=$M$9,M21<=$O$9),VLOOKUP(BYT,uhrady!$A$2:$M$102,M21+1,FALSE),0) -> 0 | P21: 3 | Q21: =IF(AND(P21>=$M$9,P21<=$O$9),VLOOKUP(BYT,'Předpis po mesici'!$A$3:$JQ$102,P21+262,FALSE),0) -> 0 | R21: 3 | S21: =IF(AND(P21>=$M$9,P21<=$N$9),VLOOKUP(BYT,'Předpis po mesici'!$A$3:$JQ$102,P21+79,FALSE),0) -> 0 | T21: =IF(AND(P21>=$M$9,P21<=$N$9),VLOOKUP(BYT,'Předpis po mesici'!$A$3:$JQ$102,P21+1,FALSE),0) -> 0 | U21: =IF(AND(P21>=$M$9,P21<=$N$9),VLOOKUP(BYT,'Předpis po mesici'!$A$3:$JQ$102,P21+14,FALSE),0) -> 0 | V21: =IF(AND(P21>=$M$9,P21<=$N$9),VLOOKUP(BYT,'Předpis po mesici'!$A$3:$JQ$102,P21+27,FALSE),0) -> 0 | W21: =IF(AND(P21>=$M$9,P21<=$N$9),VLOOKUP(BYT,'Předpis po mesici'!$A$3:$JQ$102,P21+40,FALSE),0) -> 0 | X21: =IF(AND(P21>=$M$9,P21<=$N$9),VLOOKUP(BYT,'Předpis po mesici'!$A$3:$JQ$102,P21+53,FALSE),0) -> 0 | Y21: =IF(AND(P21>=$M$9,P21<=$N$9),VLOOKUP(BYT,'Předpis po mesici'!$A$3:$JQ$102,P21+66,FALSE),0) -> 0 | Z21: =IF(AND(P21>=$M$9,P21<=$N$9),VLOOKUP(BYT,'Předpis po mesici'!$A$3:$JQ$102,P21+92,FALSE),0) -> 0 | AA21: =IF(AND(P21>=$M$9,P21<=$N$9),VLOOKUP(BYT,'Předpis po mesici'!$A$3:$JQ$102,P21+105,FALSE),0) -> 0 | AB21: =IF(AND(P21>=$M$9,P21<=$N$9),VLOOKUP(BYT,'Předpis po mesici'!$A$3:$JQ$102,P21+118,FALSE),0) -> 0 | AC21: =IF(AND(P21>=$M$9,P21<=$N$9),VLOOKUP(BYT,'Předpis po mesici'!$A$3:$JQ$102,P21+131,FALSE),0) -> 0 | AD21: =IF(AND(P21>=$M$9,P21<=$N$9),VLOOKUP(BYT,'Předpis po mesici'!$A$3:$JQ$102,P21+170,FALSE),0) -> 0 | AE21: =IF(AND(P21>=$M$9,P21<=$N$9),VLOOKUP(BYT,'Předpis po mesici'!$A$3:$JQ$102,P21+183,FALSE),0) -> 0 | AF21: =IF(AND(P21>=$M$9,P21<=$N$9),VLOOKUP(BYT,'Předpis po mesici'!$A$3:$JQ$102,P21+196,FALSE),0) -> 0 | AG21: =IF(AND(P21>=$M$9,P21<=$N$9),VLOOKUP(BYT,'Předpis po mesici'!$A$3:$JQ$102,P21+209,FALSE),0) -> 0 | AH21: =IF(AND(P21>=$M$9,P21<=$N$9),VLOOKUP(BYT,'Předpis po mesici'!$A$3:$JQ$102,P21+222,FALSE),0) -> 0 | AI21: =IF(AND(P21>=$M$9,P21<=$N$9),VLOOKUP(BYT,'Předpis po mesici'!$A$3:$JQ$102,P21+157,FALSE),0) -> 0 | AJ21: =IF(AND(P21>=$M$9,P21<=$N$9),VLOOKUP(BYT,'Počet osob'!$A$2:$JR$102,P21+2,FALSE),0) -> 0 | AK21: =IF(AND(P21>=$M$9,P21<=$N$9),VLOOKUP(BYT,'Předpis po mesici'!$A$3:$JQ$102,P21+144,FALSE),0) -> 0 | AL21: =IF(AND(P21>=$M$9,P21<=$N$9),VLOOKUP(BYT,'Předpis po mesici'!$A$3:$JQ$102,P21+248,FALSE),0) -> 0 | AM21: =IF(AND(P21>=$M$9,P21<=$N$9),VLOOKUP(BYT,'Předpis po mesici'!$A$3:$JQ$102,P21+235,FALSE),0) -> 0 | AN21: =IF(AND(P21>=$M$9,P21<=$N$9),VLOOKUP(BYT,'Předpis po mesici'!$A$3:$JQ$102,P21+235,FALSE),0) -> 0
